Workbook
Name \103: #REF!
Name \107: #REF!
Name \108: #REF!
Name \109: #REF!
Name \112: #REF!
Name \114: #REF!
Name \115: #REF!
Name \117: #REF!
Name \118: #REF!
Name \119: #REF!
Name \120: #REF!
Name \121: #REF!
Name \123: #REF!
Name \124: #REF!
Name \125: #REF!
Name \126: #REF!
Name \128: #REF!
Name \139: #REF!
Name \140: #REF!
Name \150: #REF!
Name \154: #REF!
Name \156: #REF!
Name \157: #REF!
Name \158: #REF!
Name \160: #REF!
Name \305: #REF!
Name \323: #REF!
Name \325: #REF!
Name \326: #REF!
Name \327: #REF!
Name \328: #REF!
Name \342: #REF!
Name \346: #REF!
Name \347: #REF!
Name \348: #REF!
Name \349: #REF!
Name \353: #REF!
Name \357: #REF!
Name \358: #REF!
Name \359: #REF!
Name \4055: #REF!
Name \4057: #REF!
Name \4059: #REF!
Name \4062: #REF!
Name \4063: #REF!
Name \4064: #REF!
Name \4065: #REF!
Name \4066: #REF!
Name \4069: #REF!
Name \A: #REF!
Name \B: #REF!
Name \D: #REF!
Name \G: #REF!
Name \H: #REF!
Name \J: #REF!
Name \m: #REF!
Name \P: #REF!
Name \Q: #REF!
Name \R: #REF!
Name \S: #REF!

Sheet Nov Inv Recon
A1: Nov Vendor Inv Detail | B1: Nov Vendor Inv Detail | C1: Nov Vendor Inv Detail | D1: Nov Vendor Inv Detail | E1: Nov Vendor Inv Detail | F1: Nov Vendor Inv Detail | G1: Calculated | H1: Cognos - Nov Billing CDK | I1: Cognos - Nov Billing CDK | J1: Cognos - CDK Contract Detail | K1: Cognos - CDK Contract Detail | L1: Cognos - CDK Contract Detail | M1: Cognos - CDK Contract Detail | N1: Cognos - CDK Contract Detail | O1: Cognos - Nov Billing CDK | P1: Cognos - Nov Billing CDK | Q1: Calculated | R1: Calculated | S1: Calculated | T1: Manual | U1: Cognos - Inv Detail Packages | V1: Cognos - Inv Detail Packages | W1: Cognos - Inv Detail Packages | X1: ? | Y1: ? | Z1: ?
A2: Account | B2: Customer_ID | C2: External Billing ID | D2: Total minutes | E2: Overages | F2: Billing_amount | G2: CarWars Excl Overage | H2: CMF | I2: Ship to Name | J2: ANS Date | K2: Install Date | L2: LSS Date | M2: Catalog Number | N2: Catalog Description | O2: CDK Billing | P2: CDK Overages | Q2: CDK total Billing | R2: Margin Excl Overage | S2: Margin % Excl Overage | T2: Comment Group | U2: CDK Package 1 | V2: CDK Package 2 | W2: CDK Package 3 | X2: CallRevu Package 1 | Y2: CallRevu Package 2 | Z2: CallRevu Package 3
A3: Baker - Buick GMC Cadillac | B3: 76195 | C3: 17223 | D3: 8351.73 | E3: 0 | F3: 1571.65 | G3: =+F3-E3 -> 1571.65 | H3: 76143222 | I3: BAKER BUICK GMC CADILLAC | K3: 44707 | L3: 45808 | M3: 4570060 | N3: CRM OUTBOUND TELEPHONY TRACKING (NEW AND CONVERSION) | O3: =VLOOKUP(H3,'Billing CDK pivot'!A:C,3,FALSE) -> #N/A | P3: =IFERROR(VLOOKUP(H3,'Billing CDK pivot (overages)'!A:F,6,FALSE),0) -> 0 | Q3: =+O3+P3 -> #N/A | R3: =+O3-G3 -> #N/A | S3: =+R3/O3 -> #N/A | T3: ANS/Loss | U3: #N/A | V3: #N/A | W3: #N/A | X3: Secondary Package: Carrier Registration - Monthly ($10.00)
A4: Bob Bell Hyundai | B4: 92128 | C4: 18596 | D4: 9740.35 | E4: 0 | F4: 1581.65 | G4: =+F4-E4 -> 1581.65 | H4: 76217678 | I4: BOB BELL HYUNDAI | K4: 45566 | L4: 45914 | M4: 4570062 | N4: CARWARS PREMIUM SALES | O4: =VLOOKUP(H4,'Billing CDK pivot'!A:C,3,FALSE) -> #N/A | P4: =IFERROR(VLOOKUP(H4,'Billing CDK pivot (overages)'!A:F,6,FALSE),0) -> 0 | Q4: =+O4+P4 -> #N/A | R4: =+O4-G4 -> #N/A | S4: =+R4/O4 -> #N/A | T4: ANS/Loss | U4: #N/A | V4: #N/A | W4: #N/A | X4: Secondary Package: Carrier Registration - Monthly ($10.00) | Y4: Elead CW Unlimited v2 ($1,571.65)
A5: Cella Ford | B5: 90338 | C5: 8230 | D5: 2477.75 | E5: 0 | F5: 264.15 | G5: =+F5-E5 -> 264.15 | H5: 08320047 | I5: CELLA FORD | K5: 44053 | L5: 45961 | M5: 4570009 | N5: CARWARS STARTER 3500 | O5: =VLOOKUP(H5,'Billing CDK pivot'!A:C,3,FALSE) -> #N/A | P5: =IFERROR(VLOOKUP(H5,'Billing CDK pivot (overages)'!A:F,6,FALSE),0) -> 0 | Q5: =+O5+P5 -> #N/A | R5: =+O5-G5 -> #N/A | S5: =+R5/O5 -> #N/A | T5: ANS/Loss | U5: #N/A | V5: #N/A | W5: #N/A | X5: Secondary Package: Carrier Registration - Monthly ($10.00) | Y5: Elead CW Starter 4000 v2 ($254.15)
A6: Fair Oaks CDJR | B6: 93471 | C6: 10445 | D6: 0 | E6: 0 | F6: 1793.3 | G6: =+F6-E6 -> 1793.3 | H6: 76003426 | I6: FAIR OAKS CHANTILLY CHRYSLER DODGE JEEP RAM | K6: 44053 | L6: 45961 | M6: 4570009 | N6: CARWARS STARTER 3500 | O6: =VLOOKUP(H6,'Billing CDK pivot'!A:C,3,FALSE) -> #N/A | P6: =IFERROR(VLOOKUP(H6,'Billing CDK pivot (overages)'!A:F,6,FALSE),0) -> 0 | Q6: =+O6+P6 -> #N/A | R6: =+O6-G6 -> #N/A | S6: =+R6/O6 -> #N/A | T6: ANS/Loss | U6: #N/A | V6: #N/A | W6: #N/A | X6: eLead - CW Starter - 7500 mins v2 ($424.15) | Y6: eLead - CW Premium - Sales 50k v2 ($1,571.65) | Z6: Secondary Package: eLead - Car Wars Texting v2 ($211.65)
A7: Fredy KIA | B7: 116892 | C7: 6397 | D7: 52.02 | E7: 0 | F7: 1581.65 | G7: =+F7-E7 -> 1581.65 | H7: 76062949 | I7: FREDY KIA | K7: 43862 | L7: 45869 | M7: =VLOOKUP(H7,'Billing CDK pivot'!A:C,3,FALSE) -> #N/A | N7: =VLOOKUP(I7,'Billing CDK pivot'!B:D,3,FALSE) -> #N/A | O7: =VLOOKUP(H7,'Billing CDK pivot'!A:C,3,FALSE) -> #N/A | P7: =IFERROR(VLOOKUP(H7,'Billing CDK pivot (overages)'!A:F,6,FALSE),0) -> 0 | Q7: =+O7+P7 -> #N/A | R7: =+O7-G7 -> #N/A | S7: =+R7/O7 -> #N/A | T7: ANS/Loss | U7: #N/A | V7: #N/A | W7: #N/A | X7: eLead - CW Starter - 3500 mins v2 ($254.15) | Y7: eLead - CW Premium - Sales 50k v2 ($1,571.65)
A8: King KIA | B8: 86863 | C8: 18077 | D8: 4423.02 | E8: 29.19 | F8: 293.34 | G8: =+F8-E8 -> 264.15 | H8: 76049589 | I8: KING KIA | K8: 44013 | L8: 45777 | M8: 4570009 | N8: CARWARS STARTER 3500 | O8: =VLOOKUP(H8,'Billing CDK pivot'!A:C,3,FALSE) -> #N/A | P8: =IFERROR(VLOOKUP(H8,'Billing CDK pivot (overages)'!A:F,6,FALSE),0) -> 0 | Q8: =+O8+P8 -> #N/A | R8: =+O8-G8 -> #N/A | S8: =+R8/O8 -> #N/A | T8: ANS/Loss | U8: #N/A | V8: #N/A | W8: #N/A | X8: Secondary Package: Carrier Registration - Monthly ($10.00) | Y8: Elead CW Starter 4000 v2 ($254.15)
A9: King Kia of Laurel | B9: 150401 | C9: 27069 | D9: 9933.82 | E9: 443.93 | F9: 708.08 | G9: =+F9-E9 -> 264.15 | H9: 76230032 | I9: KING KIA OF LAUREL | K9: 44663 | L9: 45777 | M9: 4570009 | N9: CARWARS STARTER 3500 | O9: =VLOOKUP(H9,'Billing CDK pivot'!A:C,3,FALSE) -> #N/A | P9: =IFERROR(VLOOKUP(H9,'Billing CDK pivot (overages)'!A:F,6,FALSE),0) -> 0 | Q9: =+O9+P9 -> #N/A | R9: =+O9-G9 -> #N/A | S9: =+R9/O9 -> #N/A | T9: ANS/Loss | U9: #N/A | V9: #N/A | W9: #N/A | X9: Secondary Package: Carrier Registration - Monthly ($10.00) | Y9: eLead - CW Starter - 3500 mins v2 ($254.15)
A10: King Volkswagen | B10: 86862 | C10: 18076 | D10: 4425.79 | E10: 29.38 | F10: 293.53 | G10: =+F10-E10 -> 264.15 | H10: 76049571 | I10: KING VOLKSWAGEN | K10: 44013 | L10: 45777 | M10: 4570009 | N10: CARWARS STARTER 3500 | O10: =VLOOKUP(H10,'Billing CDK pivot'!A:C,3,FALSE) -> #N/A | P10: =IFERROR(VLOOKUP(H10,'Billing CDK pivot (overages)'!A:F,6,FALSE),0) -> 0 | Q10: =+O10+P10 -> #N/A | R10: =+O10-G10 -> #N/A | S10: =+R10/O10 -> #N/A | T10: ANS/Loss | U10: #N/A | V10: #N/A | W10: #N/A | X10: Secondary Package: Carrier Registration - Monthly ($10.00) | Y10: Elead CW Starter 4000 v2 ($254.15)
A11: Lokey Nissan | B11: 148843 | C11: 10786 | D11: 0 | E11: 0 | F11: 0 | G11: =+F11-E11 -> 0 | H11: 76211594 | I11: LOKEY NISSAN | K11: 45545 | L11: 45961 | M11: 4571030 | N11: CARWARS STARTER 5000 | O11: =VLOOKUP(H11,'Billing CDK pivot'!A:C,3,FALSE) -> #N/A | P11: =IFERROR(VLOOKUP(H11,'Billing CDK pivot (overages)'!A:F,6,FALSE),0) -> 0 | Q11: =+O11+P11 -> #N/A | R11: =+O11-G11 -> #N/A | S11: =+R11/O11 -> #N/A | T11: ANS/Loss | U11: #N/A | V11: #N/A | W11: #N/A | X11: eLead - Elite Small v2 ($1,274.15)
A12: Mel Hambelton Ford | B12: 116785 | C12: 19638 | D12: 43 | E12: 0 | F12: 1571.65 | G12: =+F12-E12 -> 1571.65 | H12: 76049550 | I12: MEL HAMBELTON FORD | K12: 44657 | L12: 45777 | M12: 4570062 | N12: CARWARS PREMIUM SALES | O12: =VLOOKUP(H12,'Billing CDK pivot'!A:C,3,FALSE) -> #N/A | P12: =IFERROR(VLOOKUP(H12,'Billing CDK pivot (overages)'!A:F,6,FALSE),0) -> 0 | Q12: =+O12+P12 -> #N/A | R12: =+O12-G12 -> #N/A | S12: =+R12/O12 -> #N/A | T12: ANS/Loss | U12: #N/A | V12: #N/A | W12: #N/A | X12: Secondary Package: Carrier Registration - Monthly ($10.00)
A13: Midlands Toyota | B13: 46377 | C13: 8725 | D13: 36 | E13: 0 | F13: 0 | G13: =+F13-E13 -> 0 | H13: 76228629 | I13: MIDLANDS TOYOTA | K13: 44568 | L13: 45716 | M13: 4570058 | N13: CARWARS STARTER 7500 | O13: =VLOOKUP(H13,'Billing CDK pivot'!A:C,3,FALSE) -> #N/A | P13: =IFERROR(VLOOKUP(H13,'Billing CDK pivot (overages)'!A:F,6,FALSE),0) -> 0 | Q13: =+O13+P13 -> #N/A | R13: =+O13-G13 -> #N/A | S13: =+R13/O13 -> #N/A | T13: ANS/Loss | U13: #N/A | V13: #N/A | W13: #N/A | X13: Secondary Package: Carrier Registration - Monthly ($10.00)
A14: Mobile Bay Harley Davidson | B14: 99628 | C14: 17155 | D14: 1264.34 | E14: 0 | F14: 264.15 | G14: =+F14-E14 -> 264.15 | H14: 76211956 | I14: MOBILE BAY HARLEY DAVIDSON | K14: 43862 | L14: 45777 | M14: 4570060 | N14: CRM OUTBOUND TELEPHONY TRACKING (NEW AND CONVERSION) | O14: =VLOOKUP(H14,'Billing CDK pivot'!A:C,3,FALSE) -> #N/A | P14: =IFERROR(VLOOKUP(H14,'Billing CDK pivot (overages)'!A:F,6,FALSE),0) -> 0 | Q14: =+O14+P14 -> #N/A | R14: =+O14-G14 -> #N/A | S14: =+R14/O14 -> #N/A | T14: ANS/Loss | U14: #N/A | V14: #N/A | W14: #N/A | X14: Secondary Package: Carrier Registration - Monthly ($10.00) | Y14: eLead - CW Starter - 3500 mins v2 ($254.15)
A15: New Orleans Harley Davidson | B15: 99624 | C15: 4548 | D15: 42.65 | E15: 0 | F15: 139 | G15: =+F15-E15 -> 139 | H15: 76211900 | I15: NEW ORLEANS HARLEY-DAVIDSON | K15: 43862 | L15: 45777 | M15: 4570060 | N15: CRM OUTBOUND TELEPHONY TRACKING (NEW AND CONVERSION) | O15: =VLOOKUP(H15,'Billing CDK pivot'!A:C,3,FALSE) -> #N/A | P15: =IFERROR(VLOOKUP(H15,'Billing CDK pivot (overages)'!A:F,6,FALSE),0) -> 0 | Q15: =+O15+P15 -> #N/A | R15: =+O15-G15 -> #N/A | S15: =+R15/O15 -> #N/A | T15: ANS/Loss | U15: #N/A | V15: #N/A | W15: #N/A | X15: Elead Outbound 4000 v2 ($129.00) | Y15: Elead Outbound 4000 v2 ($129.00)
A16: Piazza Nissan of Ardmore | B16: 142901 | C16: 23308 | D16: 0 | E16: 0 | F16: 254.15 | G16: =+F16-E16 -> 254.15 | H16: 76215011 | I16: PIAZZA NISSAN OF ARDMORE | K16: 44118 | L16: 45900 | M16: 4570009 | N16: CARWARS STARTER 3500 | O16: =VLOOKUP(H16,'Billing CDK pivot'!A:C,3,FALSE) -> #N/A | P16: =IFERROR(VLOOKUP(H16,'Billing CDK pivot (overages)'!A:F,6,FALSE),0) -> 0 | Q16: =+O16+P16 -> #N/A | R16: =+O16-G16 -> #N/A | S16: =+R16/O16 -> #N/A | T16: ANS/Loss | U16: #N/A | V16: #N/A | W16: #N/A | X16: Secondary Package: Carrier Registration - Monthly ($10.00)
A17: Renaldo Kia | B17: 154381 | C17: 9560 | D17: 2 | E17: 0 | F17: 434.15 | G17: =+F17-E17 -> 434.15 | H17: 76171765 | I17: RENALDO KIA | K17: 44958 | L17: 45930 | M17: 4570058 | N17: CARWARS STARTER 7500 | O17: =VLOOKUP(H17,'Billing CDK pivot'!A:C,3,FALSE) -> #N/A | P17: =IFERROR(VLOOKUP(H17,'Billing CDK pivot (overages)'!A:F,6,FALSE),0) -> 0 | Q17: =+O17+P17 -> #N/A | R17: =+O17-G17 -> #N/A | S17: =+R17/O17 -> #N/A | T17: ANS/Loss | U17: #N/A | V17: #N/A | W17: #N/A | X17: Secondary Package: Carrier Registration - Monthly ($10.00) | Y17: eLead - CW Starter - 7500 mins v2 ($424.15)
A18: Rosedale Chevrolet | B18: 59676 | C18: 11619 | D18: 11274.29 | E18: 449.14 | F18: 1298.14 | G18: =+F18-E18 -> 849 | H18: 76055608 | I18: ROSEDALE CHEVROLET | K18: 43965 | L18: 45930 | M18: 4570383 | N18: EL1OUTCALLTRACK (GM IMR) | O18: =VLOOKUP(H18,'Billing CDK pivot'!A:C,3,FALSE) -> #N/A | P18: =IFERROR(VLOOKUP(H18,'Billing CDK pivot (overages)'!A:F,6,FALSE),0) -> 0 | Q18: =+O18+P18 -> #N/A | R18: =+O18-G18 -> #N/A | S18: =+R18/O18 -> #N/A | T18: ANS/Loss | U18: #N/A | V18: #N/A | W18: #N/A | X18: Secondary Package: Carrier Registration - Monthly ($10.00) | Y18: Elead - 24' CW Elite Small ($839.00)
A19: Union Auto Grupo Usados | B19: 145682 | C19: 25433 | D19: 0 | E19: 0 | F19: 254.15 | G19: =+F19-E19 -> 254.15 | H19: 76224283 | I19: UNION AUTO GRUPO USADOS | K19: 44305 | L19: 45869 | M19: 4570009 | N19: CARWARS STARTER 3500 | O19: =VLOOKUP(H19,'Billing CDK pivot'!A:C,3,FALSE) -> #N/A | P19: =IFERROR(VLOOKUP(H19,'Billing CDK pivot (overages)'!A:F,6,FALSE),0) -> 0 | Q19: =+O19+P19 -> #N/A | R19: =+O19-G19 -> #N/A | S19: =+R19/O19 -> #N/A | T19: ANS/Loss | U19: #N/A | V19: #N/A | W19: #N/A | X19: eLead - CW Starter - 3500 mins v2 ($254.15)
A20: Stanley Ford Sweetwater | B20: 97584 | C20: 18849 | D20: 8390.85 | E20: 61.47 | F20: 495.62 | G20: =+F20-E20 -> 434.15 | H20: 76166962 | I20: STANLEY FORD SWEETWATER | K20: 43862 | L20: 43878 | M20: 4570060 | N20: CRM OUTBOUND TELEPHONY TRACKING (NEW AND CONVERSION) | O20: =VLOOKUP(H20,'Billing CDK pivot'!A:C,3,FALSE) -> #N/A | P20: =IFERROR(VLOOKUP(H20,'Billing CDK pivot (overages)'!A:F,6,FALSE),0) -> 0 | Q20: =+O20+P20 -> #N/A | R20: =+O20-G20 -> #N/A | S20: =+R20/O20 -> #N/A | T20: ANS/Loss - Click to all active and reason on CLM of billing line is that this is downgrading to Carwars starter 7500 from carwars advanced sales - no billing though | U20: #N/A | V20: #N/A | W20: #N/A | X20: Secondary Package: Carrier Registration - Monthly ($10.00) | Y20: eLead - CW Starter - 7500 mins v2 ($424.15)
A21: McSweeney Auto Group Clanton LLC | B21: 187780 | C21: 76201662 | D21: 4406.98 | E21: 0 | F21: 1653 | G21: =+F21-E21 -> 1653 | H21: 76201662 | I21: MCSWEENEY CHRYSLER DODGE JEEP RAM | K21: 45390 | L21: 45595 | M21: 4570289 | N21: CARWARS ELITE 12,500 PACKAGE | O21: =VLOOKUP(H21,'Billing CDK pivot'!A:C,3,FALSE) -> #N/A | P21: =IFERROR(VLOOKUP(H21,'Billing CDK pivot (overages)'!A:F,6,FALSE),0) -> 0 | Q21: =+O21+P21 -> #N/A | R21: =+O21-G21 -> #N/A | S21: =+R21/O21 -> #N/A | T21: ANS/Loss - Deactivated Apr - Reactive as of Sept | U21: #N/A | V21: #N/A | W21: #N/A | X21: eLead - CW Starter - 3500 mins v2 ($254.15) | Y21: Elead - 24' CW Elite Medium ($1,294.00) | Z21: Secondary Package: Elead - 24' CW Elite Medium Service ($349.00)
A22: Modern Nissan of Lake Norman | B22: 131763 | C22: 21795 | D22: 3176.66 | E22: 0 | F22: 264.15 | G22: =+F22-E22 -> 264.15 | H22: 76165887 | I22: MODERN NISSAN OF LAKE NORMAN | K22: 43862 | L22: 45322 | M22: 4570060 | N22: CRM OUTBOUND TELEPHONY TRACKING (NEW AND CONVERSION) | O22: =VLOOKUP(H22,'Billing CDK pivot'!A:C,3,FALSE) -> #N/A | P22: =IFERROR(VLOOKUP(H22,'Billing CDK pivot (overages)'!A:F,6,FALSE),0) -> 0 | Q22: =+O22+P22 -> #N/A | R22: =+O22-G22 -> #N/A | S22: =+R22/O22 -> #N/A | T22: ANS/Loss - sent form but Carwars said dealer wanted to keep it but no billing - sent email to sales | U22: #N/A | V22: #N/A | W22: #N/A | X22: Secondary Package: Carrier Registration - Monthly ($10.00) | Y22: eLead - CW Starter - 3500 mins v2 ($254.15)
A23: Zimbrick Acura of Brookfield | B23: 141131 | C23: 15952 | D23: 1584.05 | E23: 0 | F23: 434.15 | G23: =+F23-E23 -> 434.15 | H23: 76066612 | I23: ZIMBRICK ACURA OF BROOKFIELD | K23: 44082 | L23: 45412 | M23: 4570058 | N23: CARWARS STARTER 7500 | O23: =VLOOKUP(H23,'Billing CDK pivot'!A:C,3,FALSE) -> #N/A | P23: =IFERROR(VLOOKUP(H23,'Billing CDK pivot (overages)'!A:F,6,FALSE),0) -> 0 | Q23: =+O23+P23 -> #N/A | R23: =+O23-G23 -> #N/A | S23: =+R23/O23 -> #N/A | T23: ANS/Loss - sent to carwars 8/12/25 | U23: #N/A | V23: #N/A | W23: #N/A | X23: eLead - Elite Small ($1,019.00) | Y23: eLead - CW Starter - 7500 mins v2 ($424.15)
A24: Bob Bell Ford | B24: 59246 | C24: 18577 | D24: 13420.63 | E24: 0 | F24: 1581.65 | G24: =+F24-E24 -> 1581.65 | H24: 25181201 | I24: BOB BELL FORD | J24: 45526 | M24: 4570062 | N24: CARWARS PREMIUM SALES | O24: =VLOOKUP(H24,'Billing CDK pivot'!A:C,3,FALSE) -> #N/A | P24: =IFERROR(VLOOKUP(H24,'Billing CDK pivot (overages)'!A:F,6,FALSE),0) -> 0 | Q24: =+O24+P24 -> #N/A | R24: =+O24-G24 -> #N/A | S24: =+R24/O24 -> #N/A | T24: ANS/Loss - Sent to carwars 8/8/25 | U24: #N/A | V24: #N/A | W24: #N/A | X24: Secondary Package: Carrier Registration - Monthly ($10.00) | Y24: eLead - CW Premium - Sales 50k v2 ($1,571.65)
A25: Moonshine Harley Davidson | B25: 119133 | C25: 4545 | D25: 6999.72 | E25: 0 | F25: 499 | G25: =+F25-E25 -> 499 | H25: 76253988 | I25: MOONSHINE HARLEY-DAVIDSON | M25: 4570060 | N25: CARWARS LEISURE SMALL (SALES ONLY) | O25: =VLOOKUP(H25,'Billing CDK pivot'!A:C,3,FALSE) -> #N/A | P25: =IFERROR(VLOOKUP(H25,'Billing CDK pivot (overages)'!A:F,6,FALSE),0) -> 0 | Q25: =+O25+P25 -> #N/A | R25: =+O25-G25 -> #N/A | S25: =+R25/O25 -> #N/A | T25: Margin >30% | U25: #N/A | V25: #N/A | W25: #N/A | X25: Secondary Package: Carrier Registration - Monthly ($10.00) | Y25: eLead - CW Leisure Small (Sales Only) ($489.00)
A26: HAN - Audi Jacksonville | B26: 94617 | C26: 17989 | D26: 0.99 | E26: 0 | F26: 139 | G26: =+F26-E26 -> 139 | H26: 76200288 | I26: AUDI JACKSONVILLE | K26: 43862 | L26: 45688 | M26: 4570060 | N26: CRM OUTBOUND TELEPHONY TRACKING (NEW AND CONVERSION) | O26: =VLOOKUP(H26,'Billing CDK pivot'!A:C,3,FALSE) -> #N/A | P26: =IFERROR(VLOOKUP(H26,'Billing CDK pivot (overages)'!A:F,6,FALSE),0) -> 0 | Q26: =+O26+P26 -> #N/A | R26: =+O26-G26 -> #N/A | S26: =+R26/O26 -> #N/A | T26: Moved to call Revu | U26: #N/A | V26: #N/A | W26: #N/A | X26: Secondary Package: Carrier Registration - Monthly ($10.00) | Y26: Elead Outbound 4000 v2 ($129.00)
A27: HAN - Coconut Point Honda | B27: 146561 | C27: 15230 | D27: 0 | E27: 0 | F27: 1284.15 | G27: =+F27-E27 -> 1284.15 | H27: 76177675 | I27: COCONUT POINT HONDA | K27: 44461 | L27: 45713 | M27: 4570289 | N27: CARWARS ELITE 12,500 PACKAGE | O27: =VLOOKUP(H27,'Billing CDK pivot'!A:C,3,FALSE) -> #N/A | P27: =IFERROR(VLOOKUP(H27,'Billing CDK pivot (overages)'!A:F,6,FALSE),0) -> 0 | Q27: =+O27+P27 -> #N/A | R27: =+O27-G27 -> #N/A | S27: =+R27/O27 -> #N/A | T27: Moved to call Revu | U27: #N/A | V27: #N/A | W27: #N/A | X27: Secondary Package: Carrier Registration - Monthly ($10.00) | Y27: eLead - Elite Small v2 ($1,274.15)
A28: Infiniti of Tallahassee | B28: 115609 | C28: 19515 | D28: 243.17 | E28: 0 | F28: 264.15 | G28: =+F28-E28 -> 264.15 | H28: 76208041 | I28: KRAFT INFINITI | K28: 43862 | L28: 45273 | M28: 4570060 | N28: CRM OUTBOUND TELEPHONY TRACKING (NEW AND CONVERSION) | O28: =VLOOKUP(H28,'Billing CDK pivot'!A:C,3,FALSE) -> #N/A | P28: =IFERROR(VLOOKUP(H28,'Billing CDK pivot (overages)'!A:F,6,FALSE),0) -> 0 | Q28: =+O28+P28 -> #N/A | R28: =+O28-G28 -> #N/A | S28: =+R28/O28 -> #N/A | T28: Moved to call Revu | U28: #N/A | V28: #N/A | W28: #N/A | X28: Secondary Package: Carrier Registration - Monthly ($10.00) | Y28: eLead - CW Starter - 3500 mins v2 ($254.15)
A29: Keyser and Miller Ford | B29: 117484 | C29: 19910 | D29: 0 | E29: 0 | F29: 254.15 | G29: =+F29-E29 -> 254.15 | H29: 76067593 | I29: KEYSER & MILLER FORD | K29: 43862 | L29: 45273 | M29: 4570060 | N29: CRM OUTBOUND TELEPHONY TRACKING (NEW AND CONVERSION) | O29: =VLOOKUP(H29,'Billing CDK pivot'!A:C,3,FALSE) -> #N/A | P29: =IFERROR(VLOOKUP(H29,'Billing CDK pivot (overages)'!A:F,6,FALSE),0) -> 0 | Q29: =+O29+P29 -> #N/A | R29: =+O29-G29 -> #N/A | S29: =+R29/O29 -> #N/A | T29: Moved to call Revu | U29: #N/A | V29: #N/A | W29: #N/A | X29: Secondary Package: Carrier Registration - Monthly ($10.00)
A30: Murray Chrysler Dodge Jeep Ram | B30: 90442 | C30: 18231 | D30: 0 | E30: 0 | F30: 424.15 | G30: =+F30-E30 -> 424.15 | H30: 76167994 | I30: MURRAY CHRYSLER DODGE JEEP | K30: 43862 | L30: 44500 | M30: 4570060 | N30: CRM OUTBOUND TELEPHONY TRACKING (NEW AND CONVERSION) | O30: =VLOOKUP(H30,'Billing CDK pivot'!A:C,3,FALSE) -> #N/A | P30: =IFERROR(VLOOKUP(H30,'Billing CDK pivot (overages)'!A:F,6,FALSE),0) -> 0 | Q30: =+O30+P30 -> #N/A | R30: =+O30-G30 -> #N/A | S30: =+R30/O30 -> #N/A | T30: Moved to Call Revu in 2021 | U30: #N/A | V30: #N/A | W30: #N/A | X30: Secondary Package: Carrier Registration - Monthly ($10.00)
A31: North Point CJDR | B31: 81644 | C31: 17721 | D31: 16020.29 | E31: 0 | F31: 1581.65 | G31: =+F31-E31 -> 1581.65 | H31: 01326364 | I31: NORTH POINT CHRYSLER DODGE JEEP RAM | M31: =VLOOKUP(H31,'Billing CDK pivot (by package)'!A:D,3,FALSE) -> 4570060 | N31: =VLOOKUP(H31,'Billing CDK pivot (by package)'!A:D,4,FALSE) -> CRM OUTBOUND TELEPHONY TRACKING (NEW AND CONVERSION) | O31: =VLOOKUP(H31,'Billing CDK pivot'!A:C,3,FALSE) -> #N/A | P31: =IFERROR(VLOOKUP(H31,'Billing CDK pivot (overages)'!A:F,6,FALSE),0) -> 0 | Q31: =+O31+P31 -> #N/A | R31: =+O31-G31 -> #N/A | S31: =+R31/O31 -> #N/A | T31: Negative Margin | U31: CRM OUTBOUND TELEPHONY TRACKING (NEW AND CONVERSION) ($131.04) | X31: Secondary Package: Carrier Registration - Monthly ($10.00) | Y31: Elead CW Unlimited v2 ($1,571.65)
A32: Holman NC - Leith Autopark Wendell | B32: 61226 | C32: 16386 | D32: 13441.24 | E32: 426.58 | F32: 1295.73 | G32: =+F32-E32 -> 869.15 | H32: 71039289 | I32: LEITH AUTO PARK KIA | M32: =VLOOKUP(H32,'Billing CDK pivot (by package)'!A:D,3,FALSE) -> #N/A | N32: =VLOOKUP(H32,'Billing CDK pivot (by package)'!A:D,4,FALSE) -> #N/A | O32: =VLOOKUP(H32,'Billing CDK pivot'!A:C,3,FALSE) -> #N/A | P32: =IFERROR(VLOOKUP(H32,'Billing CDK pivot (overages)'!A:F,6,FALSE),0) -> 0 | Q32: =+O32+P32 -> #N/A | R32: =+O32-G32 -> #N/A | S32: =+R32/O32 -> #N/A | T32: Negative Margin | U32: CRM OUTBOUND TELEPHONY TRACKING (NEW AND CONVERSION) ($199.00) | V32: CARWARS INDEFINITE CALL RECORDINGS ($10.00) | X32: Secondary Package: Carrier Registration - Monthly ($10.00) | Y32: eLead - CW Advanced - Sales - 7500 mins v2 ($849.15) | Z32: Secondary Package: Long Term Audio Storage - $10 ($10.00)
A33: Bruce Bennett Nissan of Danbury | B33: 154578 | C33: 27016 | D33: 14366.1 | E33: 0 | F33: 1581.65 | G33: =+F33-E33 -> 1581.65 | H33: 76225899 | I33: DANBURY NISSAN INFINITI | M33: =VLOOKUP(H33,'Billing CDK pivot (by package)'!A:D,3,FALSE) -> #N/A | N33: =VLOOKUP(H33,'Billing CDK pivot (by package)'!A:D,4,FALSE) -> #N/A | O33: =VLOOKUP(H33,'Billing CDK pivot'!A:C,3,FALSE) -> #N/A | P33: =IFERROR(VLOOKUP(H33,'Billing CDK pivot (overages)'!A:F,6,FALSE),0) -> 0 | Q33: =+O33+P33 -> #N/A | R33: =+O33-G33 -> #N/A | S33: =+R33/O33 -> #N/A | T33: Negative Margin | U33: CARWARS STARTER 7500 ($499.00) | X33: Elead Launch Phase-0 ($0.00) | Y33: eLead - CW Premium - Sales 50k v2 ($1,571.65)
A34: Zimbrick BMW | B34: 56397 | C34: 15949 | D34: 9173.52 | E34: 80.97 | F34: 525.12 | G34: =+F34-E34 -> 444.15 | H34: 76066617 | I34: ZIMBRICK BMW | M34: =VLOOKUP(H34,'Billing CDK pivot (by package)'!A:D,3,FALSE) -> #N/A | N34: =VLOOKUP(H34,'Billing CDK pivot (by package)'!A:D,4,FALSE) -> #N/A | O34: =VLOOKUP(H34,'Billing CDK pivot'!A:C,3,FALSE) -> #N/A | P34: =IFERROR(VLOOKUP(H34,'Billing CDK pivot (overages)'!A:F,6,FALSE),0) -> 0 | Q34: =+O34+P34 -> #N/A | R34: =+O34-G34 -> #N/A | S34: =+R34/O34 -> #N/A | T34: Negative Margin | U34: CRM OUTBOUND TELEPHONY TRACKING (NEW AND CONVERSION) ($142.17) | X34: Secondary Package: Carrier Registration - Monthly ($10.00) | Y34: Elead CW Starter 8000 v2 ($424.15) | Z34: Secondary Package: Long Term Audio Storage - $10 ($10.00)
A35: Zimbrick Chevrolet | B35: 56395 | C35: 15949 | D35: 1040.22 | E35: 0 | F35: 434.15 | G35: =+F35-E35 -> 434.15 | H35: 76161145 | I35: ZIMBRICK CHEVROLET | M35: =VLOOKUP(H35,'Billing CDK pivot (by package)'!A:D,3,FALSE) -> #N/A | N35: =VLOOKUP(H35,'Billing CDK pivot (by package)'!A:D,4,FALSE) -> #N/A | O35: =VLOOKUP(H35,'Billing CDK pivot'!A:C,3,FALSE) -> #N/A | P35: =IFERROR(VLOOKUP(H35,'Billing CDK pivot (overages)'!A:F,6,FALSE),0) -> 0 | Q35: =+O35+P35 -> #N/A | R35: =+O35-G35 -> #N/A | S35: =+R35/O35 -> #N/A | T35: Negative Margin | U35: CRM OUTBOUND TELEPHONY TRACKING (NEW AND CONVERSION) ($142.17) | X35: Secondary Package: Carrier Registration - Monthly ($10.00) | Y35: Elead CW Starter 8000 v2 ($424.15)
A36: Zimbrick Mini | B36: 56403 | C36: 15949 | D36: 1760.72 | E36: 0 | F36: 434.15 | G36: =+F36-E36 -> 434.15 | H36: 76069427 | I36: ZIMBRICK MINI | M36: =VLOOKUP(H36,'Billing CDK pivot (by package)'!A:D,3,FALSE) -> #N/A | N36: =VLOOKUP(H36,'Billing CDK pivot (by package)'!A:D,4,FALSE) -> #N/A | O36: =VLOOKUP(H36,'Billing CDK pivot'!A:C,3,FALSE) -> #N/A | P36: =IFERROR(VLOOKUP(H36,'Billing CDK pivot (overages)'!A:F,6,FALSE),0) -> 0 | Q36: =+O36+P36 -> #N/A | R36: =+O36-G36 -> #N/A | S36: =+R36/O36 -> #N/A | T36: Negative Margin | U36: CRM OUTBOUND TELEPHONY TRACKING (NEW AND CONVERSION) ($142.17) | X36: eLead - Elite Small ($1,019.00) | Y36: Elead CW Starter 8000 v2 ($424.15)
A37: Holman NC - Leith Porsche Cary | B37: 61225 | C37: 16380 | D37: 8772.33 | E37: 0 | F37: 1581.65 | G37: =+F37-E37 -> 1581.65 | H37: 01021838 | I37: LEITH PORSCHE | M37: =VLOOKUP(H37,'Billing CDK pivot (by package)'!A:D,3,FALSE) -> 4571030 | N37: =VLOOKUP(H37,'Billing CDK pivot (by package)'!A:D,4,FALSE) -> CARWARS STARTER 5000 | O37: =VLOOKUP(H37,'Billing CDK pivot'!A:C,3,FALSE) -> #N/A | P37: =IFERROR(VLOOKUP(H37,'Billing CDK pivot (overages)'!A:F,6,FALSE),0) -> 0 | Q37: =+O37+P37 -> #N/A | R37: =+O37-G37 -> #N/A | S37: =+R37/O37 -> #N/A | T37: Negative Margin | U37: CARWARS STARTER 5000 ($599.00) | X37: Secondary Package: Carrier Registration - Monthly ($10.00) | Y37: eLead - CW Premium - Sales 50k v2 ($1,571.65)
A38: Holman NC - Leith Maserati of Raleigh | B38: 61222 | C38: 16370 | D38: 3014.34 | E38: 0 | F38: 1581.65 | G38: =+F38-E38 -> 1581.65 | H38: 76025122 | I38: MASERATI OF RALEIGH | M38: =VLOOKUP(H38,'Billing CDK pivot (by package)'!A:D,3,FALSE) -> #N/A | N38: =VLOOKUP(H38,'Billing CDK pivot (by package)'!A:D,4,FALSE) -> #N/A | O38: =VLOOKUP(H38,'Billing CDK pivot'!A:C,3,FALSE) -> #N/A | P38: =IFERROR(VLOOKUP(H38,'Billing CDK pivot (overages)'!A:F,6,FALSE),0) -> 0 | Q38: =+O38+P38 -> #N/A | R38: =+O38-G38 -> #N/A | S38: =+R38/O38 -> #N/A | T38: Negative Margin | U38: CARWARS INDEFINITE CALL RECORDINGS ($20.00) | V38: CARWARS STARTER 5000 ($599.00) | X38: Secondary Package: Carrier Registration - Monthly ($10.00) | Y38: eLead - CW Premium - Sales 50k v2 ($1,571.65)
A39: Modern Subaru of Boone | B39: 131769 | C39: 21831 | D39: 1393.76 | E39: 0 | F39: 434.15 | G39: =+F39-E39 -> 434.15 | H39: 76162431 | I39: MODERN SUBARU OF BOONE | M39: =VLOOKUP(H39,'Billing CDK pivot (by package)'!A:D,3,FALSE) -> #N/A | N39: =VLOOKUP(H39,'Billing CDK pivot (by package)'!A:D,4,FALSE) -> #N/A | O39: =VLOOKUP(H39,'Billing CDK pivot'!A:C,3,FALSE) -> #N/A | P39: =IFERROR(VLOOKUP(H39,'Billing CDK pivot (overages)'!A:F,6,FALSE),0) -> 0 | Q39: =+O39+P39 -> #N/A | R39: =+O39-G39 -> #N/A | S39: =+R39/O39 -> #N/A | T39: Negative Margin | U39: CARWARS STARTER 3500 ($200.93) | X39: Secondary Package: Carrier Registration - Monthly ($10.00) | Y39: eLead - CW Starter - 7500 mins v2 ($424.15)
A40: Holman NC - Leith Audi Raleigh | B40: 61230 | C40: 16397 | D40: 2412.18 | E40: 0 | F40: 1581.65 | G40: =+F40-E40 -> 1581.65 | H40: 76072454 | I40: AUDI RALEIGH | M40: =VLOOKUP(H40,'Billing CDK pivot (by package)'!A:D,3,FALSE) -> #N/A | N40: =VLOOKUP(H40,'Billing CDK pivot (by package)'!A:D,4,FALSE) -> #N/A | O40: =VLOOKUP(H40,'Billing CDK pivot'!A:C,3,FALSE) -> #N/A | P40: =IFERROR(VLOOKUP(H40,'Billing CDK pivot (overages)'!A:F,6,FALSE),0) -> 0 | Q40: =+O40+P40 -> #N/A | R40: =+O40-G40 -> #N/A | S40: =+R40/O40 -> #N/A | T40: Negative Margin | U40: CARWARS INDEFINITE CALL RECORDINGS ($20.00) | V40: CARWARS STARTER UNLIMITED (FOR PHONE SYSTEMS) ($799.00) | X40: Secondary Package: Carrier Registration - Monthly ($10.00) | Y40: eLead - CW Premium - Sales 50k v2 ($1,571.65)
...

Sheet VictoryHeitrich
A1: Vendor Invoice Detail | D1: CDK Invoice Detail | I1: NOV Billing CDK | J1: ? | K1: ? | L1: Manual
A2: Account | B2: Customer_ID | C2: External Billing ID | D2: CMF | E2: Name | F2: Install Date | G2: LSS Date | H2: Catalog Number | I2: Nov Recurring | J2: Nov Overages | K2: Nov Bill | L2: Comments/updated eleadID
A3: VA - Ocean Honda Milford | B3: 188878 | C3: 32166 | D3: 76257348 | E3: OCEAN HONDA MILFORD | F3: 45978 | H3: CAR WARS CUSTOM PACKAGE--VICTORY AUTO | I3: =VLOOKUP(D3,'Billing CDK pivot'!A:C,3,FALSE) -> #N/A | K3: 731.91273 | L3: Dec Billing
A4: VA - Ocean Honda of Ventura | B4: 143170 | C4: 9448 | D4: 76217400 | E4: OCEAN HONDA OF VENTURA | F4: 44230 | G4: 45810 | H4: CAR WARS CUSTOM PACKAGE--VICTORY AUTO | I4: =VLOOKUP(D4,'Billing CDK pivot'!A:C,3,FALSE) -> #N/A | K4: 731.91273 | L4: LSS
A5: VA - Victory Chrysler Dodge Jeep Ram | B5: 187886 | C5: 30697 | D5: 76188954 | E5: VICTORY CHRYSLER DODGE JEEP RAM | F5: 44230 | G5: 45169 | H5: CAR WARS CUSTOM PACKAGE--VICTORY AUTO | I5: =VLOOKUP(D5,'Billing CDK pivot'!A:C,3,FALSE) -> #N/A | K5: 731.91273 | L5: LSS
A6: Crossroads Hyundai of Loveland at Centerra | B6: 59103 | C6: 16318 | D6: 76243306 | E6: CROSSROADS HYUNDAI | H6: =VLOOKUP(D6,'Billing CDK pivot (by package)'!A:D,4,FALSE) -> #N/A | I6: =VLOOKUP(D6,'Billing CDK pivot'!A:C,3,FALSE) -> #N/A | K6: 185 | L6: No Call Tracking Catalog
A7: VA - Albany Subaru | B7: 136870 | D7: 76228429 | E7: ALBANY SUBARU | H7: =VLOOKUP(D7,'Billing CDK pivot (by package)'!A:D,4,FALSE) -> CAR WARS CUSTOM PACKAGE--VICTORY AUTO | I7: =VLOOKUP(D7,'Billing CDK pivot'!A:C,3,FALSE) -> #N/A | K7: 731.91273 | L7: OK
A8: VA - Auburn Honda | B8: 143054 | C8: 7314 | D8: 76202512 | E8: AUBURN HONDA | H8: =VLOOKUP(D8,'Billing CDK pivot (by package)'!A:D,4,FALSE) -> CAR WARS CUSTOM PACKAGE--VICTORY AUTO | I8: =VLOOKUP(D8,'Billing CDK pivot'!A:C,3,FALSE) -> #N/A | K8: 731.91273 | L8: OK
A9: VA - BMW of Humboldt Bay | B9: 177594 | C9: 29917 | D9: 76245927 | E9: BMW OF HUMBOLDT BAY | H9: =VLOOKUP(D9,'Billing CDK pivot (by package)'!A:D,4,FALSE) -> CAR WARS CUSTOM PACKAGE--VICTORY AUTO | I9: =VLOOKUP(D9,'Billing CDK pivot'!A:C,3,FALSE) -> #N/A | K9: 731.91273 | L9: OK
A10: VA - Chevrolet Milan | B10: 143053 | C10: 24233 | D10: 76202505 | E10: VICTORY CHEVROLET BUICK | H10: =VLOOKUP(D10,'Billing CDK pivot (by package)'!A:D,4,FALSE) -> CAR WARS CUSTOM PACKAGE--VICTORY AUTO | I10: =VLOOKUP(D10,'Billing CDK pivot'!A:C,3,FALSE) -> #N/A | K10: 731.91273 | L10: OK
A11: VA - Cookevillle Honda | B11: 143165 | C11: 2590 | D11: 76202499 | E11: COOKEVILLE HONDA | H11: =VLOOKUP(D11,'Billing CDK pivot (by package)'!A:D,4,FALSE) -> CAR WARS CUSTOM PACKAGE--VICTORY AUTO | I11: =VLOOKUP(D11,'Billing CDK pivot'!A:C,3,FALSE) -> #N/A | K11: 731.91273 | L11: OK
A12: VA - Dave Kirk Chevrolet GMC | B12: 154889 | C12: 22473 | D12: 76235670 | E12: DAVE KIRK AUTOMOTIVE | H12: =VLOOKUP(D12,'Billing CDK pivot (by package)'!A:D,4,FALSE) -> CAR WARS CUSTOM PACKAGE--VICTORY AUTO | I12: =VLOOKUP(D12,'Billing CDK pivot'!A:C,3,FALSE) -> #N/A | K12: 731.91273 | L12: OK
A13: VA - East Tennessee Dodge | B13: 143046 | C13: 2217 | D13: 76202568 | E13: EAST TENNESSEE DODGE CHRYSLER JEEP | H13: =VLOOKUP(D13,'Billing CDK pivot (by package)'!A:D,4,FALSE) -> CAR WARS CUSTOM PACKAGE--VICTORY AUTO | I13: =VLOOKUP(D13,'Billing CDK pivot'!A:C,3,FALSE) -> #N/A | K13: 731.91273 | L13: OK
A14: VA - East Tennessee Ford | B14: 143071 | C14: 9917 | D14: 76202498 | E14: EAST TENNESSEE FORD | H14: =VLOOKUP(D14,'Billing CDK pivot (by package)'!A:D,4,FALSE) -> CAR WARS CUSTOM PACKAGE--VICTORY AUTO | I14: =VLOOKUP(D14,'Billing CDK pivot'!A:C,3,FALSE) -> #N/A | K14: 731.91273 | L14: OK
A15: VA - Freeway Toyota | B15: 143062 | C15: 11370 | D15: 76179964 | E15: FREEWAY TOYOTA OF HANFORD | H15: =VLOOKUP(D15,'Billing CDK pivot (by package)'!A:D,4,FALSE) -> CAR WARS CUSTOM PACKAGE--VICTORY AUTO | I15: =VLOOKUP(D15,'Billing CDK pivot'!A:C,3,FALSE) -> #N/A | K15: 731.91273 | L15: OK
A16: VA - Freeway Toyota of Gilroy | B16: 153483 | D16: 76228607 | E16: FREEWAY TOYOTA OF GILROY | H16: =VLOOKUP(D16,'Billing CDK pivot (by package)'!A:D,4,FALSE) -> CAR WARS CUSTOM PACKAGE--VICTORY AUTO | I16: =VLOOKUP(D16,'Billing CDK pivot'!A:C,3,FALSE) -> #N/A | K16: 731.91273 | L16: OK
A17: VA - Honda of Jackson | B17: 143173 | C17: 3334 | D17: 76202492 | E17: VICTORY HONDA OF JACKSON | H17: =VLOOKUP(D17,'Billing CDK pivot (by package)'!A:D,4,FALSE) -> CAR WARS CUSTOM PACKAGE--VICTORY AUTO | I17: =VLOOKUP(D17,'Billing CDK pivot'!A:C,3,FALSE) -> #N/A | K17: 731.91273 | L17: OK
A18: VA - Honda of Monroe | B18: 143060 | C18: 2631 | D18: 76202491 | E18: VICTORY HONDA OF MONROE | H18: =VLOOKUP(D18,'Billing CDK pivot (by package)'!A:D,4,FALSE) -> CAR WARS CUSTOM PACKAGE--VICTORY AUTO | I18: =VLOOKUP(D18,'Billing CDK pivot'!A:C,3,FALSE) -> #N/A | K18: 731.91273 | L18: OK
A19: VA - Honda of Morgan Hill | B19: 143174 | C19: 19709 | D19: 76214531 | E19: VICTORY HONDA OF MORGAN HILL | H19: =VLOOKUP(D19,'Billing CDK pivot (by package)'!A:D,4,FALSE) -> CAR WARS CUSTOM PACKAGE--VICTORY AUTO | I19: =VLOOKUP(D19,'Billing CDK pivot'!A:C,3,FALSE) -> #N/A | K19: 731.91273 | L19: OK
A20: VA - Honda of Muncie | B20: 143175 | C20: 2229 | D20: 76202355 | E20: VICTORY HONDA OF MUNCIE | H20: =VLOOKUP(D20,'Billing CDK pivot (by package)'!A:D,4,FALSE) -> CAR WARS CUSTOM PACKAGE--VICTORY AUTO | I20: =VLOOKUP(D20,'Billing CDK pivot'!A:C,3,FALSE) -> #N/A | K20: 731.91273 | L20: OK
A21: VA - Honda of Plymouth | B21: 143178 | C21: 2226 | D21: 76202360 | E21: VICTORY HONDA OF PLYMOUTH | H21: =VLOOKUP(D21,'Billing CDK pivot (by package)'!A:D,4,FALSE) -> CAR WARS CUSTOM PACKAGE--VICTORY AUTO | I21: =VLOOKUP(D21,'Billing CDK pivot'!A:C,3,FALSE) -> #N/A | K21: 731.91273 | L21: OK
A22: VA - Kastner Honda | B22: 153318 | D22: 76232648 | E22: KASTNER HONDA | H22: =VLOOKUP(D22,'Billing CDK pivot (by package)'!A:D,4,FALSE) -> CAR WARS CUSTOM PACKAGE--VICTORY AUTO | I22: =VLOOKUP(D22,'Billing CDK pivot'!A:C,3,FALSE) -> #N/A | K22: 731.91273 | L22: OK
A23: VA - Lexus Monterey Peninsula | B23: 143063 | C23: 17614 | D23: 76211755 | E23: LEXUS MONTEREY PENINSULA | H23: =VLOOKUP(D23,'Billing CDK pivot (by package)'!A:D,4,FALSE) -> CAR WARS CUSTOM PACKAGE--VICTORY AUTO | I23: =VLOOKUP(D23,'Billing CDK pivot'!A:C,3,FALSE) -> #N/A | K23: 731.91273 | L23: OK
A24: VA - Marin County Ford | B24: 143073 | C24: 9982 | D24: 76169916 | E24: MARIN COUNTY FORD | H24: =VLOOKUP(D24,'Billing CDK pivot (by package)'!A:D,4,FALSE) -> CAR WARS CUSTOM PACKAGE--VICTORY AUTO | I24: =VLOOKUP(D24,'Billing CDK pivot'!A:C,3,FALSE) -> #N/A | K24: 731.91273 | L24: OK
A25: VA - Melody Toyota | B25: 143064 | C25: 1032 | D25: 76202911 | E25: VICTORY TOYOTA OF SAN BRUNO | H25: =VLOOKUP(D25,'Billing CDK pivot (by package)'!A:D,4,FALSE) -> CAR WARS CUSTOM PACKAGE--VICTORY AUTO | I25: =VLOOKUP(D25,'Billing CDK pivot'!A:C,3,FALSE) -> #N/A | K25: 731.91273 | L25: OK
A26: VA - Nissan West Dickson | B26: 143181 | C26: 2739 | D26: 76202353 | E26: VICTORY NISSAN WEST | H26: =VLOOKUP(D26,'Billing CDK pivot (by package)'!A:D,4,FALSE) -> CAR WARS CUSTOM PACKAGE--VICTORY AUTO | I26: =VLOOKUP(D26,'Billing CDK pivot'!A:C,3,FALSE) -> #N/A | K26: 731.91273 | L26: OK
A27: VA - Ocean Honda | B27: 143167 | C27: 5331 | D27: 76202509 | E27: OCEAN HONDA | H27: =VLOOKUP(D27,'Billing CDK pivot (by package)'!A:D,4,FALSE) -> CAR WARS CUSTOM PACKAGE--VICTORY AUTO | I27: =VLOOKUP(D27,'Billing CDK pivot'!A:C,3,FALSE) -> #N/A | K27: 731.91273 | L27: OK
A28: VA - Ocean Honda Groton | B28: 188256 | C28: 31836 | D28: 76255144 | E28: OCEAN HONDA GROTON | H28: =VLOOKUP(D28,'Billing CDK pivot (by package)'!A:D,4,FALSE) -> CAR WARS CUSTOM PACKAGE--VICTORY AUTO | I28: =VLOOKUP(D28,'Billing CDK pivot'!A:C,3,FALSE) -> #N/A | K28: 731.91273 | L28: OK
A29: VA - Ocean Honda of Brockton | B29: 143055 | C29: 16820 | D29: 76216792 | E29: OCEAN HONDA OF BROCKTON | H29: CAR WARS CUSTOM PACKAGE--VICTORY AUTO | I29: =VLOOKUP(D29,'Billing CDK pivot'!A:C,3,FALSE) -> #N/A | K29: 731.91273 | L29: OK
A30: VA - Ocean Honda of Burlingame | B30: 143168 | C30: 17105 | D30: 76212419 | E30: OCEAN HONDA OF BURLINGAME | H30: CAR WARS CUSTOM PACKAGE--VICTORY AUTO | I30: =VLOOKUP(D30,'Billing CDK pivot'!A:C,3,FALSE) -> #N/A | K30: 731.91273 | L30: OK
A31: VA - Ocean Honda of Weymouth | B31: 143057 | C31: 13780 | D31: 76211538 | E31: OCEAN HONDA OF HANOVER | H31: CAR WARS CUSTOM PACKAGE--VICTORY AUTO | I31: =VLOOKUP(D31,'Billing CDK pivot'!A:C,3,FALSE) -> #N/A | K31: 731.91273 | L31: OK
A32: VA - Ocean Honda of Whittier | B32: 143171 | C32: 16461 | D32: 76202508 | E32: OCEAN HONDA OF WHITTIER | H32: CAR WARS CUSTOM PACKAGE--VICTORY AUTO | I32: =VLOOKUP(D32,'Billing CDK pivot'!A:C,3,FALSE) -> #N/A | K32: 731.91273 | L32: OK
A33: VA - Ocean Subaru of Fullerton | B33: 143182 | C33: 24244 | D33: 76217403 | E33: OCEAN SUBARU | H33: CAR WARS CUSTOM PACKAGE--VICTORY AUTO | I33: =VLOOKUP(D33,'Billing CDK pivot'!A:C,3,FALSE) -> #N/A | K33: 731.91273 | L33: OK
A34: VA - San Francisco Honda | B34: 143059 | C34: 15809 | D34: 76204566 | E34: SAN FRANCISCO HONDA ACURA | H34: CAR WARS CUSTOM PACKAGE--VICTORY AUTO | I34: =VLOOKUP(D34,'Billing CDK pivot'!A:C,3,FALSE) -> #N/A | K34: 731.91273 | L34: OK
A35: VA - Tower Honda | B35: 143172 | C35: 15136 | D35: 76202671 | E35: TOWER HONDA OF LONGVIEW | H35: CAR WARS CUSTOM PACKAGE--VICTORY AUTO | I35: =VLOOKUP(D35,'Billing CDK pivot'!A:C,3,FALSE) -> #N/A | K35: 731.91273 | L35: OK
A36: VA - Toyota of Canton | B36: 143185 | C36: 2221 | D36: 76125298 | E36: VICTORY TOYOTA OF CANTON | H36: CAR WARS CUSTOM PACKAGE--VICTORY AUTO | I36: =VLOOKUP(D36,'Billing CDK pivot'!A:C,3,FALSE) -> #N/A | K36: 731.91273 | L36: OK
A37: VA - Toyota of Midtown | B37: 143611 | C37: 24390 | D37: 76221153 | E37: VICTORY TOYOTA OF MIDTOWN | H37: CAR WARS CUSTOM PACKAGE--VICTORY AUTO | I37: =VLOOKUP(D37,'Billing CDK pivot'!A:C,3,FALSE) -> #N/A | K37: 731.91273 | L37: OK
A38: VA - Toyota of Seaside | B38: 143186 | C38: 17613 | D38: 76164812 | E38: VICTORY TOYOTA | H38: CAR WARS CUSTOM PACKAGE--VICTORY AUTO | I38: =VLOOKUP(D38,'Billing CDK pivot'!A:C,3,FALSE) -> #N/A | K38: 731.91273 | L38: OK
A39: VA - Tri Cities Chrysler Dodge Jeep Ram | B39: 143049 | C39: 8335 | D39: 76202493 | E39: TRI-CITIES CHRYSLER DODGE JEEP RAM | H39: CAR WARS CUSTOM PACKAGE--VICTORY AUTO | I39: =VLOOKUP(D39,'Billing CDK pivot'!A:C,3,FALSE) -> #N/A | K39: 731.91273 | L39: OK
A40: VA - Victory Chevrolet GMC Highlands | B40: 159095 | C40: 29415 | D40: 76242001 | E40: VICTORY CHEVROLET GMC HIGHLANDS | H40: CAR WARS CUSTOM PACKAGE--VICTORY AUTO | I40: =VLOOKUP(D40,'Billing CDK pivot'!A:C,3,FALSE) -> #N/A | K40: 731.91273 | L40: OK
...

Sheet Detail1
A1: Details for Count of Account - Comment Group: CDK no Charge
A3: Account | B3: Customer_ID | C3: External Billing ID | D3: Total minutes | E3: Overages | F3: Billing_amount | G3: CarWars Excl Overage | H3: CMF | I3: Ship to Name | J3: ANS Date | K3: Install Date | L3: LSS Date | M3: Catalog Number | N3: Catalog Description | O3: CDK Billing | P3: CDK Overages | Q3: CDK total Billing | R3: Margin Excl Overage | S3: Margin % Excl Overage | T3: Comment Group | U3: CDK Package 1 | V3: CDK Package 2 | W3: CDK Package 3 | X3: CallRevu Package 1 | Y3: CallRevu Package 2 | Z3: CallRevu Package 3
A4: Staunton Chrysler Dodge Jeep RAM | B4: 79668 | C4: 17662 | D4: 2844.43 | E4: 0 | F4: 254.15 | G4: 254.15 | H4: 76212445 | I4: STAUNTON CHRYSLER, DODGE,JEEP,RAM | M4: 4570060 | N4: CRM OUTBOUND TELEPHONY TRACKING (NEW AND CONVERSION) | O4: 0 | P4: 0 | Q4: 0 | R4: -254.15 | S4: #DIV/0! | T4: CDK no Charge | U4: CRM OUTBOUND TELEPHONY TRACKING (NEW AND CONVERSION) ($0.00) | X4: Secondary Package: Carrier Registration - Monthly ($10.00)

Sheet Nov Inv Recon Pivot
A3: Row Labels | B3: Count of Account | C3: Sum of Billing_amount | D3: CM Comments on process:
A4: ANS/Loss | B4: 17 | C4: 12302.74 | D4: Looked in contract detail and pulled all contract lines associated to the CMF number for the call tracking catalogs in scope. Based on manual review, determined that the most recent contract line was either in ANS or Loss status which means CDK is not billing the customer but the vendor is still billing CDK
A5: ANS/Loss - Click to all active and reason on CLM of billing line is that this is downgrading to Carwars starter 7500 from carwars advanced sales - no billing though | B5: 1 | C5: 495.62 | D5: Same comment as in row 4 but we worked with contract team to get more information.
A6: ANS/Loss - Deactivated Apr - Reactive as of Sept | B6: 1 | C6: 1653 | D6: same comment as in row 4 but received more information from Leigh Broomberg on the cancellation. She works with the vendor to cancel the lines if needed.
A7: ANS/Loss - sent form but Carwars said dealer wanted to keep it but no billing - sent email to sales | B7: 1 | C7: 264.15 | D7: same comment as in row 4 but received more information from Leigh Broomberg on the cancellation. She works with the vendor to cancel the lines if needed.
A8: ANS/Loss - sent to carwars 8/12/25 | B8: 1 | C8: 434.15 | D8: same comment as in row 4 but received more information from Leigh Broomberg on the cancellation. She works with the vendor to cancel the lines if needed. This was the date Leigh sent the cancellation to car wars but it doesn't appear the cancellation happened as we were still billed.
A9: ANS/Loss - Sent to carwars 8/8/25 | B9: 1 | C9: 1581.65 | D9: same comment as in row 4 but received more information from Leigh Broomberg on the cancellation. She works with the vendor to cancel the lines if needed. This was the date Leigh sent the cancellation to car wars but it doesn't appear the cancellation happened as we were still billed.
A10: Moved to call Revu | B10: 4 | C10: 1941.45 | D10: When I pulled contract detail I pulled all catalogs for call tracking and not just Car wars so I noticed the customer had an active call revu contract line
A11: Moved to Call Revu in 2021 | B11: 1 | C11: 424.15 | D11: When I pulled contract detail I pulled all catalogs for call tracking and not just Car wars so I noticed the customer had an active call revu contract line
A12: Negative Margin | B12: 73 | C12: 84888.83 | D12: This is just math - flagged anything with a negative margin
A13: Negative Margin - Should have been Deactivated in Sep | B13: 1 | C13: 429 | D13: This is just math - flagged anything with a negative margin. However information from Leigh Broomberg said see sent cancellation in sep but it was never cancelled on car wars side
A14: No Charge from Car wars | B14: 1 | C14: 0 | D14: Billing amount from carwars was $0 so didn't investigate these lines further
A15: No charge from Carwars | B15: 14 | C15: 0 | D15: Billing amount from carwars was $0 so didn't investigate these lines further
... A21: Margin >30% | B21: 1 | C21: 499 | D21: Bad grouping. Should have used the same grouping as row 20
A22: (blank)
A23: CDK no Charge | B23: 1 | C23: 254.15 | D23: Should have probably been included in negative margin group
A24: Grand Total | B24: 382 | C24: 308366.21

Sheet Nov Vendor Inv Detail
A1: Account | B1: Customer_ID | C1: External Billing ID | D1: Tracking_lines | E1: Dynamic_website_tracking | F1: Total Minutes | G1: Overages | H1: Minutes_Inbound | I1: Minutes_Outbound | J1: Minutes_Humanatic | K1: Price_plan | L1: Billing_amount | M1: Excl Overages
A2: Jordan Ford | B2: 61934 | C2: 16480 | D2: 16 | E2: 0 | F2: 82.34 | H2: 82.34 | I2: 0 | J2: 0 | K2: Elead CW Starter 4000 v2 | L2: 254.15 | M2: =+L2-G2 -> 254.15
A3: ELEAD1ONE CRM | B3: 8012 | D3: 2 | E3: 0 | F3: 4.67 | H3: 4.67 | I3: 0 | J3: 0 | K3: Elead Launch Phase-0 | L3: 0 | M3: =+L3-G3 -> 0
A4: ALBRECHT - INFINITI OF NORWOOD | B4: 62658 | C4: 16613 | D4: 21 | E4: 0 | F4: 1890.85 | H4: 1890.85 | I4: 0 | J4: 0 | K4: eLead - CW Starter - 3500 mins v2 | L4: 254.15 | M4: =+L4-G4 -> 254.15
A5: ALBRECHT - NASHUA INFINITI | B5: 62657 | C5: 16614 | D5: 19 | E5: 0 | F5: 37.67 | H5: 37.67 | I5: 0 | J5: 0 | K5: eLead - CW Starter - 3500 mins v2 | L5: 254.15 | M5: =+L5-G5 -> 254.15
A6: ALBRECHT - NASHUA INFINITI | B6: 62657 | C6: 16614 | D6: - | E6: - | F6: - | H6: - | I6: - | J6: - | K6: Secondary Package: Carrier Registration - Monthly | L6: 10 | M6: =+L6-G6 -> 10
A7: Allan Vigil Ford Lincoln | B7: 154247 | C7: 468 | D7: 84 | E7: 0 | F7: 18325.19 | H7: 1395.62 | I7: 16929.57 | J7: 14001.79 | K7: eLead CW Elite (Sales Service AI) v2 | L7: 2533.85 | M7: =+L7-G7 -> 2533.85
A8: Allan Vigil Ford Lincoln | B8: 154247 | C8: 468 | D8: - | E8: - | F8: - | H8: - | I8: - | J8: - | K8: Secondary Package: Carrier Registration - Monthly | L8: 10 | M8: =+L8-G8 -> 10
A9: Alpha One Motors | B9: 149876 | C9: 27280 | D9: 11 | E9: 0 | F9: 13.35 | H9: 13.35 | I9: 0 | J9: 0 | K9: eLead - CW Starter - 3500 mins v2 | L9: 254.15 | M9: =+L9-G9 -> 254.15
A10: Alpha One Motors | B10: 149876 | C10: 27280 | D10: - | E10: - | F10: - | H10: - | I10: - | J10: - | K10: Secondary Package: Carrier Registration - Monthly | L10: 10 | M10: =+L10-G10 -> 10
A11: Anderson Crystal Lake BMW / Mazda | B11: 84602 | C11: 4613a | D11: 34 | E11: 0 | F11: 1140.56 | H11: 102.95 | I11: 1037.61 | J11: 0 | K11: Elead CW Starter 4000 v2 | L11: 254.15 | M11: =+L11-G11 -> 254.15
A12: Anderson Crystal Lake BMW / Mazda | B12: 84602 | C12: 4613a | D12: - | E12: - | F12: - | H12: - | I12: - | J12: - | K12: Secondary Package: Carrier Registration - Monthly | L12: 10 | M12: =+L12-G12 -> 10
A13: Apple Honda | B13: 188955 | C13: 32347 | D13: 0 | E13: 0 | F13: 0 | H13: 0 | I13: 0 | J13: 0 | K13: Elead Launch Phase-0 | L13: 0 | M13: =+L13-G13 -> 0
A14: Apple Honda MD | B14: 97941 | D14: 50 | E14: 0 | F14: 79.33 | H14: 16.66 | I14: 62.67 | J14: 72.02 | K14: Elead - 24' CW Elite Medium | L14: 1294 | M14: =+L14-G14 -> 1294
A15: Apple Honda MD | B15: 97941 | D15: - | E15: - | F15: - | H15: - | I15: - | J15: - | K15: Secondary Package: Carrier Registration - Monthly | L15: 10 | M15: =+L15-G15 -> 10
A16: Apple Tree Superstore | B16: 99534 | C16: 19240 | D16: 3 | E16: 0 | F16: 6415.46 | G16: 48.31 | H16: 523.99 | I16: 5891.47 | J16: 0 | K16: Elead Outbound 4000 v2 | L16: 177.31 | M16: =+L16-G16 -> 129
A17: Apple Tree Superstore | B17: 99534 | C17: 19240 | D17: - | E17: - | F17: - | H17: - | I17: - | J17: - | K17: Secondary Package: Carrier Registration - Monthly | L17: 10 | M17: =+L17-G17 -> 10
A18: Arrive n Drive | B18: 187858 | C18: 30006 | D18: 12 | E18: 0 | F18: 3126.83 | H18: 626.69 | I18: 2500.14 | J18: 0 | K18: eLead - CW Starter - 5000 mins v2 | L18: 509.15 | M18: =+L18-G18 -> 509.15
A19: Athens BMW | B19: 84739 | C19: 18059 | D19: 10 | E19: 0 | F19: 1292.64 | H19: 278.72 | I19: 1013.92 | J19: 0 | K19: eLead - CW Starter - 7500 mins v2 | L19: 424.15 | M19: =+L19-G19 -> 424.15
A20: Athens BMW | B20: 84739 | C20: 18059 | D20: - | E20: - | F20: - | H20: - | I20: - | J20: - | K20: Secondary Package: Carrier Registration - Monthly | L20: 10 | M20: =+L20-G20 -> 10
A21: Audi Miami South | B21: 185463 | C21: 29715 | D21: 53 | E21: 0 | F21: 3608.44 | H21: 2979.4 | I21: 629.04 | J21: 2283.28 | K21: Elead - CW Elite Small + Advanced Service | L21: 1688 | M21: =+L21-G21 -> 1688
A22: Audi Miami South | B22: 185463 | C22: 29715 | D22: - | E22: - | F22: - | H22: - | I22: - | J22: - | K22: Secondary Package: Carrier Registration - Monthly | L22: 10 | M22: =+L22-G22 -> 10
A23: Baker - Buick GMC Cadillac | B23: 76195 | C23: 17223 | D23: 82 | E23: 0 | F23: 8351.73 | H23: 8351.73 | I23: 0 | J23: 1596.02 | K23: Elead CW Unlimited v2 | L23: 1571.65 | M23: =+L23-G23 -> 1571.65
A24: Berglund Toyota | B24: 96547 | C24: 7862 | D24: 37 | E24: 0 | F24: 2965.1 | H24: 2894.11 | I24: 70.99 | J24: 645.7 | K24: Elead CW Unlimited v2 | L24: 1571.65 | M24: =+L24-G24 -> 1571.65
A25: Bill Black Chevrolet Cadillac | B25: 142323 | C25: 22425 | D25: 14 | E25: 0 | F25: 679.89 | H25: 77.33 | I25: 602.56 | J25: 0 | K25: eLead - CW Starter - 7500 mins v2 | L25: 424.15 | M25: =+L25-G25 -> 424.15
A26: Bill Black Chevrolet Cadillac | B26: 142323 | C26: 22425 | D26: - | E26: - | F26: - | H26: - | I26: - | J26: - | K26: Secondary Package: Carrier Registration - Monthly | L26: 10 | M26: =+L26-G26 -> 10
A27: BMW/MINI of the Main Line | B27: 74464 | C27: 16765 | D27: 129 | E27: 0 | F27: 24179.12 | H27: 18067.14 | I27: 6111.98 | J27: 6130.54 | K27: eLead - CW Premium - Sales 50k v2 | L27: 1571.65 | M27: =+L27-G27 -> 1571.65
A28: BMW/MINI of the Main Line | B28: 74464 | C28: 16765 | D28: - | E28: - | F28: - | H28: - | I28: - | J28: - | K28: Secondary Package: Carrier Registration - Monthly | L28: 10 | M28: =+L28-G28 -> 10
A29: Bob Bell Ford | B29: 59246 | C29: 18577 | D29: 17 | E29: 0 | F29: 13420.63 | H29: 7548.65 | I29: 5871.98 | J29: 5617.04 | K29: eLead - CW Premium - Sales 50k v2 | L29: 1571.65 | M29: =+L29-G29 -> 1571.65
A30: Bob Bell Ford | B30: 59246 | C30: 18577 | D30: - | E30: - | F30: - | H30: - | I30: - | J30: - | K30: Secondary Package: Carrier Registration - Monthly | L30: 10 | M30: =+L30-G30 -> 10
A31: Bob Bell Hyundai | B31: 92128 | C31: 18596 | D31: 76 | E31: 0 | F31: 9740.35 | H31: 5682.62 | I31: 4057.73 | J31: 8870.65 | K31: Elead CW Unlimited v2 | L31: 1571.65 | M31: =+L31-G31 -> 1571.65
A32: Bob Bell Hyundai | B32: 92128 | C32: 18596 | D32: - | E32: - | F32: - | H32: - | I32: - | J32: - | K32: Secondary Package: Carrier Registration - Monthly | L32: 10 | M32: =+L32-G32 -> 10
A33: Bob Bell Nissan | B33: 90311 | C33: 18246 | D33: 45 | E33: 0 | F33: 5375.75 | G33: 33.82 | H33: 255.14 | I33: 5120.61 | J33: 0 | K33: eLead - CW Starter - 5000 mins v2 | L33: 542.97 | M33: =+L33-G33 -> 509.15
A34: Bob Brown Chevrolet | B34: 138653 | C34: 22237 | D34: 73 | E34: 0 | F34: 4.32 | H34: 0.67 | I34: 3.65 | J34: 0 | K34: eLead CW Elite (Sales Service AI) v2 | L34: 2533.85 | M34: =+L34-G34 -> 2533.85
A35: Bob Brown Chevrolet | B35: 138653 | C35: 22237 | D35: - | E35: - | F35: - | H35: - | I35: - | J35: - | K35: Secondary Package: Carrier Registration - Monthly | L35: 10 | M35: =+L35-G35 -> 10
A36: Bob Robinson Chevrolet Buick GMC | B36: 159842 | C36: 29415 | D36: 0 | E36: 0 | F36: 0 | H36: 0 | I36: 0 | J36: 0 | K36: Elead Launch Phase-0 | L36: 0 | M36: =+L36-G36 -> 0
A37: Bruce Bennett Nissan of Danbury | B37: 154578 | C37: 27016 | D37: 54 | E37: 0 | F37: 14366.1 | H37: 4792.49 | I37: 9573.61 | J37: 12831.22 | K37: eLead - CW Premium - Sales 50k v2 | L37: 1571.65 | M37: =+L37-G37 -> 1571.65
A38: Bruce Bennett Nissan of Danbury | B38: 154578 | C38: 27016 | D38: - | E38: - | F38: - | H38: - | I38: - | J38: - | K38: Secondary Package: Carrier Registration - Monthly | L38: 10 | M38: =+L38-G38 -> 10
A39: Buchanan Auto Park | B39: 61123 | C39: 7279 | D39: 30 | E39: 0 | F39: 5108.68 | G39: 76.5 | H39: 3173.73 | I39: 1934.95 | J39: 0 | K39: Elead CW Starter 4000 v2 | L39: 330.65 | M39: =+L39-G39 -> 254.15
A40: Buchanan Auto Park | B40: 61123 | C40: 7279 | D40: - | E40: - | F40: - | H40: - | I40: - | J40: - | K40: Secondary Package: Carrier Registration - Monthly | L40: 10 | M40: =+L40-G40 -> 10
...

Sheet Vendor Inv Pivot
A3: Account | B3: Customer_ID | C3: External Billing ID | D3: Sum of Total Minutes | E3: Sum of Overages | F3: Sum of Billing_amount
A4: Jordan Ford | B4: 61934 | C4: 16480 | D4: 82.34 | E4: 0 | F4: 254.15
A5: ELEAD1ONE CRM | B5: 8012 | C5: (blank) | D5: 4.67 | E5: 0 | F5: 0
A6: ALBRECHT - INFINITI OF NORWOOD | B6: 62658 | C6: 16613 | D6: 1890.85 | E6: 0 | F6: 254.15
A7: ALBRECHT - NASHUA INFINITI | B7: 62657 | C7: 16614 | D7: 37.67 | E7: 0 | F7: 264.15
A8: Allan Vigil Ford Lincoln | B8: 154247 | C8: 468 | D8: 18325.19 | E8: 0 | F8: 2543.85
A9: Alpha One Motors | B9: 149876 | C9: 27280 | D9: 13.35 | E9: 0 | F9: 264.15
A10: Anderson Crystal Lake BMW / Mazda | B10: 84602 | C10: 4613a | D10: 1140.56 | E10: 0 | F10: 264.15
A11: Apple Honda | B11: 188955 | C11: 32347 | D11: 0 | E11: 0 | F11: 0
A12: Apple Honda MD | B12: 97941 | C12: (blank) | D12: 79.33 | E12: 0 | F12: 1304
A13: Apple Tree Superstore | B13: 99534 | C13: 19240 | D13: 6415.46 | E13: 48.31 | F13: 187.31
A14: Arrive n Drive | B14: 187858 | C14: 30006 | D14: 3126.83 | E14: 0 | F14: 509.15
A15: Athens BMW | B15: 84739 | C15: 18059 | D15: 1292.64 | E15: 0 | F15: 434.15
A16: Audi Miami South | B16: 185463 | C16: 29715 | D16: 3608.44 | E16: 0 | F16: 1698
A17: Baker - Buick GMC Cadillac | B17: 76195 | C17: 17223 | D17: 8351.73 | E17: 0 | F17: 1571.65
A18: Berglund Toyota | B18: 96547 | C18: 7862 | D18: 2965.1 | E18: 0 | F18: 1571.65
A19: Bill Black Chevrolet Cadillac | B19: 142323 | C19: 22425 | D19: 679.89 | E19: 0 | F19: 434.15
A20: BMW/MINI of the Main Line | B20: 74464 | C20: 16765 | D20: 24179.12 | E20: 0 | F20: 1581.65
A21: Bob Bell Ford | B21: 59246 | C21: 18577 | D21: 13420.63 | E21: 0 | F21: 1581.65
A22: Bob Bell Hyundai | B22: 92128 | C22: 18596 | D22: 9740.35 | E22: 0 | F22: 1581.65
A23: Bob Bell Nissan | B23: 90311 | C23: 18246 | D23: 5375.75 | E23: 33.82 | F23: 542.97
A24: Bob Brown Chevrolet | B24: 138653 | C24: 22237 | D24: 4.32 | E24: 0 | F24: 2543.85
... A49: Cloninger Toyota | B49: 108918 | C49: 19295 | D49: 0 | E49: 0 | F49: 264.15
A50: Coastal Kia | B50: 36440 | C50: 10557A | D50: 16135.7 | E50: 0 | F50: 1581.65
A51: Coconut Point Ford | B51: 156745 | C51: 3869 | D51: 3911.88 | E51: 0 | F51: 434.15
A52: Commonwealth Chevrolet | B52: 84459 | C52: 18079 | D52: 2455.53 | E52: 0 | F52: 1581.65
A53: Commonwealth Honda | B53: 84504 | C53: 18080 | D53: 1571.65 | E53: 0 | F53: 264.15
A54: Commonwealth Kia | B54: 84503 | C54: 18081 | D54: 1525.89 | E54: 0 | F54: 264.15
A55: Commonwealth Nissan | B55: 84465 | C55: 18082 | D55: 1418.84 | E55: 0 | F55: 264.15
A56: Commonwealth Volkswagen | B56: 84506 | C56: 18083 | D56: 2205.35 | E56: 0 | F56: 264.15
A57: Commuter Cars | B57: 150041 | C57: 17995 | D57: 138.12 | E57: 0 | F57: 264.15
A58: Crescent Ford | B58: 146876 | C58: 8209 | D58: 7719.1 | E58: 0 | F58: 1029
A59: DARCARS Chrysler Jeep Dodge RAM of Rockville | B59: 59903 | C59: 5252 | D59: 0.33 | E59: 0 | F59: 129
A60: DARCARS Honda | B60: 58680 | C60: 9472 | D60: 0 | E60: 0 | F60: 129
A61: DARCARS Lexus of Silver Spring | B61: 58685 | C61: 2432 | D61: 0 | E61: 0 | F61: 129
A62: David Taylor Michigan City CDJR IN | B62: 121132 | C62: 21229 | D62: 20.98 | E62: 0 | F62: 254.15
... A104: Greenway - Greenway FIAT of East Orlando | B104: 82486 | C104: 17715 | D104: 17.64 | E104: 0 | F104: 264.15
A105: Greenway - Greenway Hyundai Orlando | B105: 84240 | C105: (blank) | D105: 21950.17 | E105: 0 | F105: 2543.85
A106: Greenway - Greenway Kia of Franklin | B106: 117573 | C106: 17302 | D106: 2554.66 | E106: 0 | F106: 434.15
A107: Greenway - Greenway Kia of Hickory Hollow | B107: 79117 | C107: 17537 | D107: 12216.95 | E107: 329.34 | F107: 1069.34
...

Sheet Detail2
A1: Details for Sum of Recurring Amount (U.S.) - Ship-To Name: STAUNTON CHRYSLER, DODGE,JEEP,RAM, CMF Number: 76212445, Charge Reference: 00200283SW05, Catalog Number: 4570009, Catalog Description: CALLSOURCE (CONVERSION) (+)
A3: Business Unit Code | B3: Product Level 1 Description | C3: Product Level 2 Description | D3: Product Level 3 Description | E3: Line of Business Code | F3: Account Code | G3: Primary (Y/N/NA) | H3: Ship-To/Location State/Province | I3: One Time Amount (U.S.) | J3: Recurring Amount (U.S.) | K3: Quantity | L3: CMF Number | M3: On Carwars Inv | N3: On Heitrich/Victory | O3: Ship-To Name | P3: Transaction Type | Q3: Charge Reference | R3: CDF Id | S3: Catalog Number | T3: Catalog Description | U3: Charge Type | V3: Charge Type Description | W3: Invoice Fiscal Year | X3: Invoice Fiscal Month | Y3: Rollup Level Code | Z3: Invoice Calendar Year | AA3: Invoice Month Name | AB3: Primary / Secondary
A4: 0914 | B4: ELEAD | C4: ELEAD OTHER | D4: CALL TRACKING COUNT AS ONE | E4: 21112 | F4: 4111001 | G4: N | H4: IL | I4: 0 | J4: 0 | K4: 1 | L4: 76212445 | M4: 76212445 | N4: #N/A | O4: STAUNTON CHRYSLER, DODGE,JEEP,RAM | P4: US INVOICE | Q4: 67035312SW04 | R4: 67035312SW04 | S4: 4570060 | T4: CRM OUTBOUND TELEPHONY TRACKING (NEW AND CONVERSION) | U4: SWW | V4: SW ACCESS VIA WEB | W4: 2025 | X4: 11 | Y4: FIN5030 | Z4: 2025 | AA4: November | AB4: Primary

Sheet Billing CDK pivot
A1: Charge Reference | B1: (Multiple Items)
A2: Catalog Number | B2: (All)
A3: Catalog Description | B3: (All)
A5: CMF Number | B5: Ship-To Name | C5: Sum of Recurring Amount (U.S.)
A6: 76212445 | B6: STAUNTON CHRYSLER, DODGE,JEEP,RAM | C6: 0
A7: Grand Total | C7: 0

Sheet Billing CDK pivot (No match)
A1: Charge Reference | B1: (Multiple Items)
A2: On Carwars Inv | B2: #N/A
A4: CMF Number | B4: Ship-To Name | C4: Catalog Number | D4: Catalog Description | E4: Sum of Recurring Amount (U.S.) | F4: Sum of One Time Amount (U.S.)
A5: 01231901 | B5: CECIL CLARK CHEVROLET | C5: 4570358 | D5: OUTBOUND CALL TRACKING PKGS (GM IMR CONVERSION) | E5: 293.02 | F5: 0
A6: 05237634 | B6: SANTA MARGARITA FORD | C6: 4570120 | D6: CRM TELEPHONY TRACKING | E6: 112 | F6: 0
A7: 08300215 | B7: HONDA KINGSTON | C7: 4570120 | D7: CRM TELEPHONY TRACKING | E7: 147.46 | F7: 0
A8: 09700154 | B8: POHANKA HONDA OF FREDERICKSBURG | C8: 4570120 | D8: CRM TELEPHONY TRACKING | E8: 65.46 | F8: 0
A9: 17272601 | B9: DON DAVIS EL CAMPO | C9: 4570060 | D9: CRM OUTBOUND TELEPHONY TRACKING (NEW AND CONVERSION) | E9: 0 | F9: 0
A10: 17272602 | B10: DON DAVIS BUICK,PONT.,GMC | C10: 4570060 | D10: CRM OUTBOUND TELEPHONY TRACKING (NEW AND CONVERSION) | E10: 0 | F10: 0
A11: 25149301 | B11: WESTBROOK HONDA | C11: 4570060 | D11: CRM OUTBOUND TELEPHONY TRACKING (NEW AND CONVERSION) | E11: 476.05 | F11: 0
A12: 25149302 | B12: HONDA OF WATERTOWN | C12: 4570060 | D12: CRM OUTBOUND TELEPHONY TRACKING (NEW AND CONVERSION) | E12: 476.05 | F12: 0
A13: 25149303 | B13: ACURA OF AVON | C13: 4570060 | D13: CRM OUTBOUND TELEPHONY TRACKING (NEW AND CONVERSION) | E13: 476.05 | F13: 0
A14: 25149304 | B14: ACURA OF MILFORD | C14: 4570060 | D14: CRM OUTBOUND TELEPHONY TRACKING (NEW AND CONVERSION) | E14: 476.05 | F14: 0
A15: 25149306 | B15: TOYOTA OF WESTBROOK | C15: 4570060 | D15: CRM OUTBOUND TELEPHONY TRACKING (NEW AND CONVERSION) | E15: 476.05 | F15: 0
A16: 25152901 | B16: BRANDFON HONDA | C16: 4570120 | D16: CRM TELEPHONY TRACKING | E16: 105 | F16: 0
... A69: 76215859 | B69: DAVE HALLMAN CHEVROLET | C69: 4570383 | D69: EL1OUTCALLTRACK (GM IMR) | E69: 1469.02 | F69: 0
C70: 4570648 | D70: SERVICE VISION PACKAGE 300 CALLS WINTEL (FOPS CMONITORING WPERFANALYTICS) | E70: 734.49 | F70: 0
A71: 76216996 | B71: SOUTHWEST INFINITI- | C71: 4570062 | D71: CARWARS PREMIUM SALES | E71: 1904.47 | F71: 0
A72: 76222492 | B72: PENSKE VOLVO PUENTE HILLS | C72: 4570120 | D72: CRM TELEPHONY TRACKING | E72: 104 | F72: 0
A73: 76222495 | B73: LAND ROVER PUENTE HILLS | C73: 4570120 | D73: CRM TELEPHONY TRACKING | E73: 104 | F73: 0
A74: 76223605 | B74: AUTOMALL AUTOMOTIVE LLC DBA TOWBIN DODGE RAM AND F | C74: 4570120 | D74: CRM TELEPHONY TRACKING | E74: 82.95 | F74: 0
A75: 76223993 | B75: GUNTERSVILLE CHEVROLET | C75: 4570120 | D75: CRM TELEPHONY TRACKING | E75: 123.81 | F75: 0
A76: 76224292 | B76: NEWTON CHEVROLET BUICK GMC | C76: 4570120 | D76: CRM TELEPHONY TRACKING | E76: 124.14 | F76: 0
A77: 76224293 | B77: NEWTON NISSAN OF GALLATIN | C77: 4570120 | D77: CRM TELEPHONY TRACKING | E77: 124.14 | F77: 0
A78: 76224320 | B78: NEWTON FORD SOUTH | C78: 4570120 | D78: CRM TELEPHONY TRACKING | E78: 105.94 | F78: 0
A79: 76225979 | B79: BERT SMITH BMW | C79: 4570104 | D79: CALLSOURCE EL ATTRIBUTED SMALL | E79: 87.59 | F79: 0
A80: 76225980 | B80: PORSCHE CLEARWATER | C80: 4570104 | D80: CALLSOURCE EL ATTRIBUTED SMALL | E80: 87.59 | F80: 0
A81: 76226123 | B81: BACHMAN BERNARD CHEVROLET GMC CADILLAC | C81: 4570120 | D81: CRM TELEPHONY TRACKING | E81: 0 | F81: 0
A82: 76227862 | B82: MATT BOWERS HYUNDAI - GULFPORT | C82: 4570009 | D82: CARWARS STARTER 3500 | E82: 322.92 | F82: 0
... A90: 76238766 | B90: FRED ANDERSON TOYOTA OF GREER | C90: 4570062 | D90: CARWARS PREMIUM SALES | E90: 1849 | F90: 0
C91: 4570124 | D91: CARWARS CARI AI | E91: 995 | F91: 0
A92: 76239770 | B92: FRED ANDERSON HYUNDAI | C92: 4570009 | D92: CARWARS STARTER 3500 | E92: 319 | F92: 0
A93: 76240559 | B93: ROBERTS CHEVROLET GMC | C93: 4570383 | D93: EL1OUTCALLTRACK (GM IMR) | E93: 1066.24 | F93: 0
C94: 4570522 | D94: SERVICE VISION PACKAGE 100 CALLS WINTEL (FOPS CMONITORING WPERFANALYTICS) | E94: 366.45 | F94: 0
A95: 76240828 | B95: MCSWEENEY AUTO GROUP CLANTON, LLC | C95: 4570129 | D95: CARWARS INDEFINITE CALL RECORDINGS | E95: 20 | F95: 0
A96: 76245381 | B96: NORTHWEST HYUNDAI | C96: 4571030 | D96: CARWARS STARTER 5000 | E96: 599 | F96: 0
A97: 76250570 | B97: ESCUDE NISSAN OF GREER | C97: 4571030 | D97: CARWARS STARTER 5000 | E97: 599 | F97: 0
A98: 76253984 | B98: MOBILE BAY HARLEY DAVIDSON | C98: 4570060 | D98: CRM OUTBOUND TELEPHONY TRACKING (NEW AND CONVERSION) | E98: 320.08 | F98: 0
A99: 76253986 | B99: SMOKIN HARLEY DAVIDSON | C99: 4570120 | D99: CRM TELEPHONY TRACKING | E99: 74.94 | F99: 0
