Workbook
Name ____gh2: {"'100'!$A$1:$M$83"}
Name ____gh2: {"'100'!$A$1:$M$83"}
Name ____gh2: {"'100'!$A$1:$M$83"}
Name ____hg2: {"'100'!$A$1:$M$83"}
Name ____hg2: {"'100'!$A$1:$M$83"}
Name ____hg2: {"'100'!$A$1:$M$83"}
Name ___gh2: {"'100'!$A$1:$M$83"}
Name ___gh2: {"'100'!$A$1:$M$83"}
Name ___gh2: {"'100'!$A$1:$M$83"}
Name ___hg2: {"'100'!$A$1:$M$83"}
Name ___hg2: {"'100'!$A$1:$M$83"}
Name ___hg2: {"'100'!$A$1:$M$83"}
Name __FDS_HYPERLINK_TOGGLE_STATE__: "ON"
Name __gh2: {"'100'!$A$1:$M$83"}
Name __gh2: {"'100'!$A$1:$M$83"}
Name __gh2: {"'100'!$A$1:$M$83"}
Name __hg2: {"'100'!$A$1:$M$83"}
Name __hg2: {"'100'!$A$1:$M$83"}
Name __hg2: {"'100'!$A$1:$M$83"}
Name _gh2: {"'100'!$A$1:$M$83"}
Name _gh2: {"'100'!$A$1:$M$83"}
Name _gh2: {"'100'!$A$1:$M$83"}
Name _hg2: {"'100'!$A$1:$M$83"}
Name _hg2: {"'100'!$A$1:$M$83"}
Name _hg2: {"'100'!$A$1:$M$83"}
Name _Order1: 0
Name _Order2: 255
Name _Regression_Int: 1
Name a: {"'Hardware Req.'!$A$1:$C$23"}
Name a: {"'Hardware Req.'!$A$1:$C$23"}
Name a: {"'Hardware Req.'!$A$1:$C$23"}
Name activations: {"'Hardware Req.'!$A$1:$C$23"}
Name activations: {"'Hardware Req.'!$A$1:$C$23"}
Name activations: {"'Hardware Req.'!$A$1:$C$23"}
Name anscount: 1
Name April: #REF!
Name AS2DocOpenMode: "AS2DocumentEdit"
Name AS2NamedRange: 6
Name AS2ReportLS: 2
Name AS2SyncStepLS: 0
Name AS2VersionLS: 300
Name Auto: [13]!Table1[[#All],[Column1]]
Name BG_Del: 15
Name BG_Ins: 4
Name BG_Mod: 6
Name Calendar10Month: '[16]NA Finance Calendar'!$D$127
Name Calendar10MonthOption: MATCH(Calendar10Month,'3.10 Cancel List'!Months,0)
Name Calendar10MonthOption: MATCH(Calendar10Month,'TV active sites in March Cancel'!Months,0)
Name Calendar10MonthOption: MATCH(Calendar10Month,Months,0)
Name Calendar10Year: '[16]NA Finance Calendar'!$C$127
Name Calendar11Month: '[16]NA Finance Calendar'!$D$141
Name Calendar11MonthOption: MATCH(Calendar11Month,'3.10 Cancel List'!Months,0)
Name Calendar11MonthOption: MATCH(Calendar11Month,'TV active sites in March Cancel'!Months,0)
Name Calendar11MonthOption: MATCH(Calendar11Month,Months,0)
Name Calendar11Year: '[16]NA Finance Calendar'!$C$141
Name Calendar12Month: '[16]NA Finance Calendar'!$D$155
Name Calendar12MonthOption: MATCH(Calendar12Month,'3.10 Cancel List'!Months,0)
Name Calendar12MonthOption: MATCH(Calendar12Month,'TV active sites in March Cancel'!Months,0)
Name Calendar12MonthOption: MATCH(Calendar12Month,Months,0)
Name Calendar12Year: '[16]NA Finance Calendar'!$C$155

Sheet Summary
C6: Billing Sites | M6: Billing Amount - Gap
D7: TruVideo Billed | E7: CDK INS | F7: CDK BLG | G7: TV Billed vs CDK INS | H7: TV Billed vs CDK INS+BLG | N7: BLG Sites | O7: Non-INS Sites on mass Cancellation list | P7: New Loss Sites since March
C8: April Prorated Billing | D8: 69 | E8: =26 -> 26 | F8: 43 | G8: =D8-E8 -> 43 | H8: =D8-E8-F8 -> 0 | M8: April- Prorated Invoice Sites | N8: =F8 -> 43
C9: May Monthly Billing | D9: 1787 | E9: =1558+22+10 -> 1590 | F9: 117 | G9: =D9-E9 -> 197 | H9: 70 | M9: April- Prorated Invoice Amount | N9: ='April Prorated Invoice-BLG Site'!F89 -> 9100.03
E10: (H+I) | F10: (J+K) | H10: (To Cancel in Invoice GAP sites) | M10: May- Monthly Invoice Sites | N10: =F9 -> 117 | O10: 39 | P10: 31
M11: May- Monthly Invoice Amount | N11: ='May Monthly Invoice- BLG Sites'!I119 -> 58850 | O11: 21300 | P11: 16450
M12: Total Amount | N12: =SUM(N9+N11) -> 67950.03 | O12: =SUM(O9+O11) -> 21300 | P12: =SUM(P9+P11) -> 16450
C14: CDK INS not billed by TruVideo | D14: ='CDK INS not Billed by TV'!J150 -> 148

Sheet May Monthly - non INS Sites
A1: CMF | B1: Customer | C1: Contract Number | D1: CMF Number | E1: CID Number | F1: Item | G1: Base Fee | H1: AI Suite Fee | I1: on March 10 Cancel list? | J1: CDK Asked TV to retain | K1: Comments - CDK Status | L1: Comments - Status Date | M1: Comments - Product | N1: Comments - Others
A2: 05088801 | B2: WINTER CHEVROLET CO. INC. | C2: T-5636 | D2: 5088801 | E2: 2503075 | F2: CDK Reseller - Base Fee | G2: 300 | H2: 200 | I2: =VLOOKUP(D2,'3.10 Cancel List'!$C:$C,1,0) -> #N/A
A3: 05236442 | B3: Smothers European | C3: T-7444 | D3: 5236442 | E3: 3001276 | F3: CDK Reseller - Base Fee | G3: 400 | H3: 200 | I3: =VLOOKUP(D3,'3.10 Cancel List'!$C:$C,1,0) -> #N/A
A4: 08300018 | B4: GRAINGER HONDA | C4: T-13310 | D4: 8300018 | E4: 3000322 | F4: CDK Reseller - Base Fee | G4: 300 | H4: 200 | I4: =VLOOKUP(D4,'3.10 Cancel List'!$C:$C,1,0) -> #N/A
A5: 13093301 | B5: MIKE FINNIN FORD | C5: T-10652 | D5: 13093301 | E5: 2503593 | F5: CDK Reseller - Base Fee | G5: 300 | H5: 200 | I5: =VLOOKUP(D5,'3.10 Cancel List'!$C:$C,1,0) -> #N/A
A6: 25297551 | B6: COLONIAL TOYOTA - CT | C6: T-9268 | D6: 25297551 | E6: 153 | F6: CDK Reseller - Base Fee | G6: 300 | H6: 200 | I6: =VLOOKUP(D6,'3.10 Cancel List'!$C:$C,1,0) -> #N/A
A7: 33049702 | B7: Don Ayres Honda | C7: T-11270 | D7: 33049702 | E7: 2700012 | F7: CDK Reseller - Base Fee | G7: 300 | H7: 200 | I7: =VLOOKUP(D7,'3.10 Cancel List'!$C:$C,1,0) -> #N/A
A8: 37216003 | B8: TC CHEVROLET | C8: T-10901 | D8: 37216003 | E8: 2700001 | F8: CDK Reseller - Base Fee | G8: 300 | H8: 200 | I8: =VLOOKUP(D8,'3.10 Cancel List'!$C:$C,1,0) -> #N/A
A9: 43996001 | B9: PAUL MILLER AUDI | C9: T-4201 | D9: 43996001 | E9: 2502552 | F9: CDK Reseller - Base Fee | G9: 450 | H9: 200 | I9: =VLOOKUP(D9,'3.10 Cancel List'!$C:$C,1,0) -> #N/A
A10: 71062428 | B10: WINTER HONDA | C10: T-5710 | D10: 71062428 | E10: 2503087 | F10: CDK Reseller - Base Fee | G10: 300 | H10: 200 | I10: =VLOOKUP(D10,'3.10 Cancel List'!$C:$C,1,0) -> #N/A
A11: 76001666 | B11: KOEPPEL NISSAN | C11: T-4093 | D11: 76001666 | E11: 2501710 | F11: CDK Reseller - Base Fee | G11: 450 | H11: 200 | I11: =VLOOKUP(D11,'3.10 Cancel List'!$C:$C,1,0) -> 76001666 | J11: Yes | K11: =VLOOKUP(D11,'March Cancel - checking results'!$C:$Q,9,0) -> LSS | L11: =VLOOKUP(D11,'March Cancel - checking results'!$C:$Q,10,0) -> 44682 | M11: =VLOOKUP(D11,'March Cancel - checking results'!$C:$Q,11,0) -> Standalone | N11: =VLOOKUP(D11,'March Cancel - checking results'!$C:$Q,15,0) -> With Inspect, no suite.
A12: 76018447 | B12: CAROLINA HYUNDAI OF HIGH POINT | C12: T-13384 | D12: 76018447 | E12: 2501591 | F12: CDK Reseller - Base Fee | G12: 300 | H12: 200 | I12: =VLOOKUP(D12,'3.10 Cancel List'!$C:$C,1,0) -> #N/A
A13: 76025293 | B13: ATLANTIC AUTO EQUIP CORP DBA ATLANTIC TOYOTA | C13: T-1024 | D13: 76025293 | E13: 2502775 | F13: CDK Reseller - Base Fee | G13: 300 | H13: 200 | I13: =VLOOKUP(D13,'3.10 Cancel List'!$C:$C,1,0) -> #N/A
A14: 76028715 | B14: JOHNSON HYUNDAI OF CARY | C14: T-4067 | D14: 76028715 | E14: 2000422 | F14: CDK Reseller - Base Fee | G14: 450 | H14: 200 | I14: =VLOOKUP(D14,'3.10 Cancel List'!$C:$C,1,0) -> 76028715 | J14: Yes | K14: =VLOOKUP(D14,'March Cancel - checking results'!$C:$M,9,0) -> LSS | L14: =VLOOKUP(D14,'March Cancel - checking results'!$C:$M,10,0) -> 45047 | M14: =VLOOKUP(D14,'March Cancel - checking results'!$C:$M,11,0) -> Standalone | N14: =VLOOKUP(D14,'March Cancel - checking results'!$C:$Q,15,0) -> Conversion LSS
A15: 76043277 | B15: PAUL MILLER HONDA OF WEST CALDWELL | C15: T-4204 | D15: 76043277 | E15: 2502505 | F15: CDK Reseller - Base Fee | G15: 450 | H15: 200 | I15: =VLOOKUP(D15,'3.10 Cancel List'!$C:$C,1,0) -> #N/A
A16: 76051500 | B16: RED BANK VOLVO | C16: T-8026 | D16: 76051500 | E16: 2503331 | F16: CDK Reseller - Base Fee | G16: 300 | H16: 200 | I16: =VLOOKUP(D16,'3.10 Cancel List'!$C:$C,1,0) -> 76051500 | J16: Yes | K16: =VLOOKUP(D16,'March Cancel - checking results'!$C:$M,9,0) -> ANS | L16: =VLOOKUP(D16,'March Cancel - checking results'!$C:$M,10,0) -> 45444 | M16: =VLOOKUP(D16,'March Cancel - checking results'!$C:$M,11,0) -> Suite | N16: =VLOOKUP(D16,'March Cancel - checking results'!$C:$Q,15,0) -> LSS lines converted from a previous ANS
A17: 76057672 | B17: MAZDA OF MILFORD | C17: T-4134 | D17: 76057672 | E17: 2501660 | F17: CDK Reseller - Base Fee | G17: 450 | H17: 200 | I17: =VLOOKUP(D17,'3.10 Cancel List'!$C:$C,1,0) -> #N/A
A18: 76097658 | B18: STATELINE MASERATI ALFA ROMEO | C18: T-14496 | D18: 76097658 | E18: 3000911 | F18: CDK Reseller - Base Fee | G18: 300 | H18: 200 | I18: =VLOOKUP(D18,'3.10 Cancel List'!$C:$C,1,0) -> 76097658 | J18: Yes | K18: =VLOOKUP(D18,'March Cancel - checking results'!$C:$M,9,0) -> LSS | L18: =VLOOKUP(D18,'March Cancel - checking results'!$C:$M,10,0) -> 45992 | M18: =VLOOKUP(D18,'March Cancel - checking results'!$C:$M,11,0) -> Suite | N18: =VLOOKUP(D18,'March Cancel - checking results'!$C:$Q,15,0) -> Whole suite LSS
A19: 76134865 | B19: REINEKE NISSAN | C19: T-13497 | D19: 76134865 | E19: 5113 | F19: CDK Reseller - Base Fee | G19: 300 | H19: 200 | I19: =VLOOKUP(D19,'3.10 Cancel List'!$C:$C,1,0) -> #N/A
A20: 76157327 | B20: MARINA DEL REY TOYOTA SCION | C20: T-4118 | D20: 76157327 | E20: 10190 | F20: CDK Reseller - Base Fee | G20: 300 | H20: 200 | I20: =VLOOKUP(D20,'3.10 Cancel List'!$C:$C,1,0) -> 76157327 | K20: =VLOOKUP(D20,'March Cancel - checking results'!$C:$M,9,0) -> ANS | L20: =VLOOKUP(D20,'March Cancel - checking results'!$C:$M,10,0) -> 45047 | M20: =VLOOKUP(D20,'March Cancel - checking results'!$C:$M,11,0) -> Suite | N20: =VLOOKUP(D20,'March Cancel - checking results'!$C:$Q,15,0) -> CDKS ANS
A21: 76173064 | B21: WEST HOUSTON INFINITI | C21: T-14518 | D21: 76173064 | E21: 3000888 | F21: CDK Reseller - Base Fee | G21: 300 | H21: 200 | I21: =VLOOKUP(D21,'3.10 Cancel List'!$C:$C,1,0) -> #N/A
A22: 76181139 | B22: Mazda of Richmond Hill | C22: T-14525 | D22: 76181139 | E22: 3000966 | F22: CDK Reseller - Base Fee | G22: 300 | H22: 200 | I22: =VLOOKUP(D22,'3.10 Cancel List'!$C:$C,1,0) -> #N/A
A23: 76184938 | B23: TAYLOR FORD LINCOLN | C23: T-14162 | D23: 76184938 | E23: 3000690 | F23: CDK Reseller - Base Fee | G23: 300 | H23: 200 | I23: =VLOOKUP(D23,'3.10 Cancel List'!$C:$C,1,0) -> #N/A
A24: 76194812 | B24: PUTNAM SUBARU BURLINGAME | C24: T-5627 | D24: 76194812 | E24: 0 | F24: CDK Reseller - Base Fee | G24: 400 | H24: 200 | I24: =VLOOKUP(D24,'3.10 Cancel List'!$C:$C,1,0) -> 76194812 | K24: =VLOOKUP(D24,'March Cancel - checking results'!$C:$M,9,0) -> LSS | L24: =VLOOKUP(D24,'March Cancel - checking results'!$C:$M,10,0) -> 45474 | M24: =VLOOKUP(D24,'March Cancel - checking results'!$C:$M,11,0) -> Standalone | N24: =VLOOKUP(D24,'March Cancel - checking results'!$C:$Q,15,0) -> Everything ANS or LSS
A25: 76197109 | B25: LEXUS OF WESLEY CHAPEL | C25: T-5929 | D25: 76197109 | E25: 2503116 | F25: CDK Reseller - Base Fee | G25: 300 | H25: 200 | I25: =VLOOKUP(D25,'3.10 Cancel List'!$C:$C,1,0) -> #N/A
A26: 76201836 | B26: VOLVO CARS WEST HOUSTON | C26: T-14393 | D26: 76201836 | E26: 3000889 | F26: CDK Reseller - Base Fee | G26: 300 | H26: 200 | I26: =VLOOKUP(D26,'3.10 Cancel List'!$C:$C,1,0) -> #N/A
A27: 76202516 | B27: KEN GANLEY TOYOTA | C27: T-6016 | D27: 76202516 | E27: 1500109 | F27: CDK Reseller - Base Fee | G27: 300 | H27: 200 | I27: =VLOOKUP(D27,'3.10 Cancel List'!$C:$C,1,0) -> 76202516 | J27: Yes | K27: =VLOOKUP(D27,'March Cancel - checking results'!$C:$M,9,0) -> LSS | L27: =VLOOKUP(D27,'March Cancel - checking results'!$C:$M,10,0) -> 45689 | M27: =VLOOKUP(D27,'March Cancel - checking results'!$C:$M,11,0) -> Suite | N27: =VLOOKUP(D27,'March Cancel - checking results'!$C:$Q,15,0) -> CDKS - LSS
A28: 76204182 | B28: Saskatoon South Hyundai | C28: T-9598 | D28: 76204182 | E28: 2001776 | F28: CDK Reseller - Base Fee | G28: 300 | H28: 200 | I28: =VLOOKUP(D28,'3.10 Cancel List'!$C:$C,1,0) -> 76204182 | J28: Yes | K28: =VLOOKUP(D28,'March Cancel - checking results'!$C:$M,9,0) -> ANS | L28: =VLOOKUP(D28,'March Cancel - checking results'!$C:$M,10,0) -> 45627 | M28: =VLOOKUP(D28,'March Cancel - checking results'!$C:$M,11,0) -> Suite | N28: =VLOOKUP(D28,'March Cancel - checking results'!$C:$Q,15,0) -> SUITE INS
A29: 76205609 | B29: FRIENDSHIP FORD LENOIR | C29: T-3955 | D29: 76205609 | E29: 2000850 | F29: CDK Reseller - Base Fee | G29: 300 | H29: 200 | I29: =VLOOKUP(D29,'3.10 Cancel List'!$C:$C,1,0) -> #N/A
A30: 76215310 | B30: DON AYRES ACURA | C30: T-10911 | D30: 76215310 | E30: 2700010 | F30: CDK Reseller - Base Fee | G30: 300 | H30: 200 | I30: =VLOOKUP(D30,'3.10 Cancel List'!$C:$C,1,0) -> #N/A
A31: 76215380 | B31: Purdy Mazda | C31: T-3912 | D31: 76215380 | E31: 2000797 | F31: CDK Reseller - Base Fee | G31: 450 | H31: 200 | I31: =VLOOKUP(D31,'3.10 Cancel List'!$C:$C,1,0) -> #N/A
A32: 76217036 | B32: CAROLINA KIA OF HIGH POINT | C32: T-11253 | D32: 76217036 | E32: 2501508 | F32: CDK Reseller - Base Fee | G32: 300 | H32: 200 | I32: =VLOOKUP(D32,'3.10 Cancel List'!$C:$C,1,0) -> #N/A
A33: 76217358 | B33: ROCKY MOUNT TOYOTA | C33: T-4254 | D33: 76217358 | E33: 3000423 | F33: CDK Reseller - Base Fee | G33: 400 | H33: 200 | I33: =VLOOKUP(D33,'3.10 Cancel List'!$C:$C,1,0) -> 76217358 | J33: Yes | K33: =VLOOKUP(D33,'March Cancel - checking results'!$C:$M,9,0) -> LSS | L33: =VLOOKUP(D33,'March Cancel - checking results'!$C:$M,10,0) -> 45383 | M33: =VLOOKUP(D33,'March Cancel - checking results'!$C:$M,11,0) -> Standalone | N33: =VLOOKUP(D33,'March Cancel - checking results'!$C:$Q,15,0) -> CDK CONVERSION - SYS GENERATED
A34: 76220331 | B34: SUBARU SOUTH TAMPA | C34: T-8125 | D34: 76220331 | E34: 2501681 | F34: CDK Reseller - Base Fee | G34: 300 | H34: 200 | I34: =VLOOKUP(D34,'3.10 Cancel List'!$C:$C,1,0) -> #N/A
A35: 76220332 | B35: SUBARU NORTH ORLANDO | C35: T-8094 | D35: 76220332 | E35: 2501684 | F35: CDK Reseller - Base Fee | G35: 300 | H35: 200 | I35: =VLOOKUP(D35,'3.10 Cancel List'!$C:$C,1,0) -> #N/A
A36: 76225712 | B36: HGREG NISSAN BUENA PARK | C36: T-3995 | D36: 76225712 | E36: 2502268 | F36: CDK Reseller - Base Fee | G36: 450 | H36: 200 | I36: =VLOOKUP(D36,'3.10 Cancel List'!$C:$C,1,0) -> 76225712 | J36: Yes | K36: =VLOOKUP(D36,'March Cancel - checking results'!$C:$M,9,0) -> LSS | L36: =VLOOKUP(D36,'March Cancel - checking results'!$C:$M,10,0) -> 45931 | M36: =VLOOKUP(D36,'March Cancel - checking results'!$C:$M,11,0) -> Suite | N36: =VLOOKUP(D36,'March Cancel - checking results'!$C:$Q,15,0) -> CDK CONVERSION - SYS GENERATED
A37: 76227121 | B37: MARTHALER HONDA TOYOTA OF ASHLAND | C37: T-4122 | D37: 76227121 | E37: 2502262 | F37: CDK Reseller - Base Fee | G37: 450 | H37: 200 | I37: =VLOOKUP(D37,'3.10 Cancel List'!$C:$C,1,0) -> 76227121 | K37: =VLOOKUP(D37,'March Cancel - checking results'!$C:$M,9,0) -> LSS | L37: =VLOOKUP(D37,'March Cancel - checking results'!$C:$M,10,0) -> 45566 | M37: =VLOOKUP(D37,'March Cancel - checking results'!$C:$M,11,0) -> Suite | N37: =VLOOKUP(D37,'March Cancel - checking results'!$C:$Q,15,0) -> Price/Value Proposition
A38: 76227134 | B38: INFINITI OF NORTHERN KENTUCKY | C38: T-9119 | D38: 76227134 | E38: 2503481 | F38: CDK Reseller - Base Fee | G38: 300 | H38: 200 | I38: =VLOOKUP(D38,'3.10 Cancel List'!$C:$C,1,0) -> 76227134 | K38: =VLOOKUP(D38,'March Cancel - checking results'!$C:$M,9,0) -> LSS | L38: =VLOOKUP(D38,'March Cancel - checking results'!$C:$M,10,0) -> 45931 | M38: =VLOOKUP(D38,'March Cancel - checking results'!$C:$M,11,0) -> Suite | N38: =VLOOKUP(D38,'March Cancel - checking results'!$C:$Q,15,0) -> Ownership Change / FOS ANS
A39: 76227679 | B39: Express Chevrolet | C39: T-9807 | D39: 76227679 | E39: 2001988 | F39: CDK Reseller - Base Fee | G39: 300 | H39: 200 | I39: =VLOOKUP(D39,'3.10 Cancel List'!$C:$C,1,0) -> 76227679 | K39: =VLOOKUP(D39,'March Cancel - checking results'!$C:$M,9,0) -> LSS | L39: =VLOOKUP(D39,'March Cancel - checking results'!$C:$M,10,0) -> 46381 | M39: =VLOOKUP(D39,'March Cancel - checking results'!$C:$M,11,0) -> Suite | N39: =VLOOKUP(D39,'March Cancel - checking results'!$C:$Q,15,0) -> CDK CONVERSION - SYS GENERATED
A40: 76227757 | B40: Spitzer Ford Dubois | C40: T-5725 | D40: 76227757 | E40: 2502508 | F40: CDK Reseller - Base Fee | G40: 400 | H40: 200 | I40: =VLOOKUP(D40,'3.10 Cancel List'!$C:$C,1,0) -> 76227757 | K40: =VLOOKUP(D40,'March Cancel - checking results'!$C:$M,9,0) -> LSS | L40: =VLOOKUP(D40,'March Cancel - checking results'!$C:$M,10,0) -> 45627 | M40: =VLOOKUP(D40,'March Cancel - checking results'!$C:$M,11,0) -> Standalone | N40: =VLOOKUP(D40,'March Cancel - checking results'!$C:$Q,15,0) -> CDK CONVERSION
...

Sheet TruVideo May Invoice Gap Sites
A1: CMF | B1: Customer | C1: Contract Number | D1: CMF Number | E1: CID Number | F1: Item | G1: Base Fee | H1: AI Suite Fee | I1: on March 10 Cancel list? | J1: Commentss | K1: Actions | L1: CDK sent Cancellation date | M1: Additional Comments | N1: new CMF
A2: 05088801 | B2: WINTER CHEVROLET CO. INC. | C2: T-5636 | D2: 5088801 | E2: 2503075 | F2: CDK Reseller - Base Fee | G2: 300 | H2: 200 | I2: No | J2: CDK Loss on 3/31/2026 | K2: To Cancel | L2: =VLOOKUP(A2,'CDK Cancel tracking 5.16.26'!$A:$E,5,0) -> #N/A
A3: 05236442 | B3: Smothers European | C3: T-7444 | D3: 5236442 | E3: 3001276 | F3: CDK Reseller - Base Fee | G3: 400 | H3: 200 | I3: No | J3: CDK Loss on 3/31/2026 | K3: To Cancel | L3: =VLOOKUP(A3,'CDK Cancel tracking 5.16.26'!$A:$E,5,0) -> 46143
A4: 08300018 | B4: GRAINGER HONDA | C4: T-13310 | D4: 8300018 | E4: 3000322 | F4: CDK Reseller - Base Fee | G4: 300 | H4: 200 | I4: No | J4: CDK Loss on 3/31/2026 | K4: To Cancel | L4: =VLOOKUP(A4,'CDK Cancel tracking 5.16.26'!$A:$E,5,0) -> 46146
A5: 13093301 | B5: MIKE FINNIN FORD | C5: T-10652 | D5: 13093301 | E5: 2503593 | F5: CDK Reseller - Base Fee | G5: 300 | H5: 200 | I5: No | J5: CDK loss on 4/30/2026 | K5: To Cancel | L5: =VLOOKUP(A5,'CDK Cancel tracking 5.16.26'!$A:$E,5,0) -> #N/A
A6: 25297551 | B6: COLONIAL TOYOTA - CT | C6: T-9268 | D6: 25297551 | E6: 153 | F6: CDK Reseller - Base Fee | G6: 300 | H6: 200 | I6: No | J6: Converted to CMF76234346 in BLG | K6: Retained | L6: =VLOOKUP(A6,'CDK Cancel tracking 5.16.26'!$A:$E,5,0) -> #N/A
A7: 33049702 | B7: Don Ayres Honda | C7: T-11270 | D7: 33049702 | E7: 2700012 | F7: CDK Reseller - Base Fee | G7: 300 | H7: 200 | I7: No | J7: no SV contract for this site found | K7: To Cancel | L7: =VLOOKUP(A7,'CDK Cancel tracking 5.16.26'!$A:$E,5,0) -> #N/A
A8: 37216003 | B8: TC CHEVROLET | C8: T-10901 | D8: 37216003 | E8: 2700001 | F8: CDK Reseller - Base Fee | G8: 300 | H8: 200 | I8: No | J8: CDK Loss on Feb 28, 2026 | K8: To Cancel | L8: =VLOOKUP(A8,'CDK Cancel tracking 5.16.26'!$A:$E,5,0) -> #N/A
A9: 43996001 | B9: PAUL MILLER AUDI | C9: T-4201 | D9: 43996001 | E9: 2502552 | F9: CDK Reseller - Base Fee | G9: 450 | H9: 200 | I9: No | J9: CDK Loss on 3/31/2026 | K9: To Cancel | L9: =VLOOKUP(A9,'CDK Cancel tracking 5.16.26'!$A:$E,5,0) -> #N/A
A10: 71062428 | B10: WINTER HONDA | C10: T-5710 | D10: 71062428 | E10: 2503087 | F10: CDK Reseller - Base Fee | G10: 300 | H10: 200 | I10: No | J10: CDK Loss on 3/31/2026 | K10: To Cancel | L10: =VLOOKUP(A10,'CDK Cancel tracking 5.16.26'!$A:$E,5,0) -> #N/A
A11: 76001666 | B11: KOEPPEL NISSAN | C11: T-4093 | D11: 76001666 | E11: 2501710 | F11: CDK Reseller - Base Fee | G11: 450 | H11: 200 | I11: =VLOOKUP(D11,'3.10 Cancel List'!$C:$C,1,0) -> 76001666 | J11: Buysell to retain - new CMF76257313- Notified TV | K11: Retained
A12: 76018447 | B12: CAROLINA HYUNDAI OF HIGH POINT | C12: T-13384 | D12: 76018447 | E12: 2501591 | F12: CDK Reseller - Base Fee | G12: 300 | H12: 200 | I12: No | J12: CDK Loss on March 15, 2026, | K12: To Cancel | L12: =VLOOKUP(A12,'CDK Cancel tracking 5.16.26'!$A:$E,5,0) -> #N/A
A13: 76025293 | B13: ATLANTIC AUTO EQUIP CORP DBA ATLANTIC TOYOTA | C13: T-1024 | D13: 76025293 | E13: 2502775 | F13: CDK Reseller - Base Fee | G13: 300 | H13: 200 | I13: No | J13: CDK loss on 4/30/2026 | K13: To Cancel | L13: =VLOOKUP(A13,'CDK Cancel tracking 5.16.26'!$A:$E,5,0) -> #N/A
A14: 76028715 | B14: JOHNSON HYUNDAI OF CARY | C14: T-4067 | D14: 76028715 | E14: 2000422 | F14: CDK Reseller - Base Fee | G14: 450 | H14: 200 | I14: =VLOOKUP(D14,'3.10 Cancel List'!$C:$C,1,0) -> 76028715 | J14: Buysell to retain - new CMF 76244599- Notified TV | K14: Retained
A15: 76043277 | B15: PAUL MILLER HONDA OF WEST CALDWELL | C15: T-4204 | D15: 76043277 | E15: 2502505 | F15: CDK Reseller - Base Fee | G15: 450 | H15: 200 | I15: No | J15: CDK Loss on 3/31/2026 | K15: To Cancel | L15: =VLOOKUP(A15,'CDK Cancel tracking 5.16.26'!$A:$E,5,0) -> 46146
A16: 76051500 | B16: RED BANK VOLVO | C16: T-8026 | D16: 76051500 | E16: 2503331 | F16: CDK Reseller - Base Fee | G16: 300 | H16: 200 | I16: =VLOOKUP(D16,'3.10 Cancel List'!$C:$C,1,0) -> 76051500 | J16: Buysell to retain - new CMF 76258384- Notified TV | K16: Retained
A17: 76057672 | B17: MAZDA OF MILFORD | C17: T-4134 | D17: 76057672 | E17: 2501660 | F17: CDK Reseller - Base Fee | G17: 450 | H17: 200 | I17: No | J17: CDK loss on 4/30/2026 | K17: To Cancel | L17: =VLOOKUP(A17,'CDK Cancel tracking 5.16.26'!$A:$E,5,0) -> #N/A
A18: 76097658 | B18: STATELINE MASERATI ALFA ROMEO | C18: T-14496 | D18: 76097658 | E18: 3000911 | F18: CDK Reseller - Base Fee | G18: 300 | H18: 200 | I18: =VLOOKUP(D18,'3.10 Cancel List'!$C:$C,1,0) -> 76097658 | J18: Buysell to retain - new CMF 76257430 - Notified TV | K18: Retained
A19: 76134865 | B19: REINEKE NISSAN | C19: T-13497 | D19: 76134865 | E19: 5113 | F19: CDK Reseller - Base Fee | G19: 300 | H19: 200 | I19: No | J19: CDK Loss on Feb 28, 2026 | K19: To Cancel | L19: =VLOOKUP(A19,'CDK Cancel tracking 5.16.26'!$A:$E,5,0) -> #N/A
A20: 76157327 | B20: MARINA DEL REY TOYOTA SCION | C20: T-4118 | D20: 76157327 | E20: 10190 | F20: CDK Reseller - Base Fee | G20: 300 | H20: 200 | I20: =VLOOKUP(D20,'3.10 Cancel List'!$C:$C,1,0) -> 76157327 | J20: ANS 05/01/2023 Suite CDKS ANS, on TV active usage list, CDK to Review | K20: To Cancel
A21: 76173064 | B21: WEST HOUSTON INFINITI | C21: T-14518 | D21: 76173064 | E21: 3000888 | F21: CDK Reseller - Base Fee | G21: 300 | H21: 200 | I21: No | J21: CDK Loss on 3/31/2026 | K21: To Cancel | L21: =VLOOKUP(A21,'CDK Cancel tracking 5.16.26'!$A:$E,5,0) -> 46146
A22: 76181139 | B22: Mazda of Richmond Hill | C22: T-14525 | D22: 76181139 | E22: 3000966 | F22: CDK Reseller - Base Fee | G22: 300 | H22: 200 | I22: No | J22: CDK Loss on 3/31/2026 | K22: To Cancel | L22: =VLOOKUP(A22,'CDK Cancel tracking 5.16.26'!$A:$E,5,0) -> #N/A
A23: 76184938 | B23: TAYLOR FORD LINCOLN | C23: T-14162 | D23: 76184938 | E23: 3000690 | F23: CDK Reseller - Base Fee | G23: 300 | H23: 200 | I23: No | J23: CDK Loss on Feb 28, 2026 | K23: To Cancel | L23: =VLOOKUP(A23,'CDK Cancel tracking 5.16.26'!$A:$E,5,0) -> #N/A
A24: 76194812 | B24: PUTNAM SUBARU BURLINGAME | C24: T-5627 | D24: 76194812 | E24: 0 | F24: CDK Reseller - Base Fee | G24: 400 | H24: 200 | I24: =VLOOKUP(D24,'3.10 Cancel List'!$C:$C,1,0) -> 76194812 | J24: LSS 07/01/2024 Standalone Everything ANS or LSS | K24: To Cancel
A25: 76197109 | B25: LEXUS OF WESLEY CHAPEL | C25: T-5929 | D25: 76197109 | E25: 2503116 | F25: CDK Reseller - Base Fee | G25: 300 | H25: 200 | I25: No | J25: CDK Loss on 3/31/2026 | K25: To Cancel | L25: =VLOOKUP(A25,'CDK Cancel tracking 5.16.26'!$A:$E,5,0) -> #N/A
A26: 76201836 | B26: VOLVO CARS WEST HOUSTON | C26: T-14393 | D26: 76201836 | E26: 3000889 | F26: CDK Reseller - Base Fee | G26: 300 | H26: 200 | I26: No | J26: CDK Loss on 3/31/2026 | K26: To Cancel | L26: =VLOOKUP(A26,'CDK Cancel tracking 5.16.26'!$A:$E,5,0) -> 46146
A27: 76202516 | B27: KEN GANLEY TOYOTA | C27: T-6016 | D27: 76202516 | E27: 1500109 | F27: CDK Reseller - Base Fee | G27: 300 | H27: 200 | I27: =VLOOKUP(D27,'3.10 Cancel List'!$C:$C,1,0) -> 76202516 | J27: CDK asked to retain | K27: Retained
A28: 76204182 | B28: Saskatoon South Hyundai | C28: T-9598 | D28: 76204182 | E28: 2001776 | F28: CDK Reseller - Base Fee | G28: 300 | H28: 200 | I28: =VLOOKUP(D28,'3.10 Cancel List'!$C:$C,1,0) -> 76204182 | J28: CDK asked to retain | K28: Retained
A29: 76205609 | B29: FRIENDSHIP FORD LENOIR | C29: T-3955 | D29: 76205609 | E29: 2000850 | F29: CDK Reseller - Base Fee | G29: 300 | H29: 200 | I29: No | J29: CDK loss on 4/30/2026 | K29: To Cancel | L29: =VLOOKUP(A29,'CDK Cancel tracking 5.16.26'!$A:$E,5,0) -> #N/A
A30: 76215310 | B30: DON AYRES ACURA | C30: T-10911 | D30: 76215310 | E30: 2700010 | F30: CDK Reseller - Base Fee | G30: 300 | H30: 200 | I30: No | J30: CDK loss on 4/30/2026 | K30: To Cancel | L30: =VLOOKUP(A30,'CDK Cancel tracking 5.16.26'!$A:$E,5,0) -> #N/A
A31: 76215380 | B31: Purdy Mazda | C31: T-3912 | D31: 76215380 | E31: 2000797 | F31: CDK Reseller - Base Fee | G31: 450 | H31: 200 | I31: No | J31: CDK Loss on Feb 28, 2026, | K31: To Cancel | L31: =VLOOKUP(A31,'CDK Cancel tracking 5.16.26'!$A:$E,5,0) -> #N/A
A32: 76217036 | B32: CAROLINA KIA OF HIGH POINT | C32: T-11253 | D32: 76217036 | E32: 2501508 | F32: CDK Reseller - Base Fee | G32: 300 | H32: 200 | I32: No | J32: CDK Loss on March 15, 2026 | K32: To Cancel | L32: =VLOOKUP(A32,'CDK Cancel tracking 5.16.26'!$A:$E,5,0) -> #N/A
A33: 76217358 | B33: ROCKY MOUNT TOYOTA | C33: T-4254 | D33: 76217358 | E33: 3000423 | F33: CDK Reseller - Base Fee | G33: 400 | H33: 200 | I33: =VLOOKUP(D33,'3.10 Cancel List'!$C:$C,1,0) -> 76217358 | J33: Buysell to retain - new CMF 76244595 - Notified TV | K33: Retained
A34: 76220331 | B34: SUBARU SOUTH TAMPA | C34: T-8125 | D34: 76220331 | E34: 2501681 | F34: CDK Reseller - Base Fee | G34: 300 | H34: 200 | I34: No | J34: CDK loss on 4/30/2026 | K34: To Cancel | L34: =VLOOKUP(A34,'CDK Cancel tracking 5.16.26'!$A:$E,5,0) -> #N/A
A35: 76220332 | B35: SUBARU NORTH ORLANDO | C35: T-8094 | D35: 76220332 | E35: 2501684 | F35: CDK Reseller - Base Fee | G35: 300 | H35: 200 | I35: No | J35: CDK loss on 4/30/2026 | K35: To Cancel | L35: =VLOOKUP(A35,'CDK Cancel tracking 5.16.26'!$A:$E,5,0) -> #N/A
A36: 76225712 | B36: HGREG NISSAN BUENA PARK | C36: T-3995 | D36: 76225712 | E36: 2502268 | F36: CDK Reseller - Base Fee | G36: 450 | H36: 200 | I36: =VLOOKUP(D36,'3.10 Cancel List'!$C:$C,1,0) -> 76225712 | J36: Buysell to retain - new CMF 76257313 - notified TV | K36: Retained
A37: 76227121 | B37: MARTHALER HONDA TOYOTA OF ASHLAND | C37: T-4122 | D37: 76227121 | E37: 2502262 | F37: CDK Reseller - Base Fee | G37: 450 | H37: 200 | I37: =VLOOKUP(D37,'3.10 Cancel List'!$C:$C,1,0) -> 76227121 | J37: LSS 10/01/2024 Suite Price/Value Proposition | K37: To Cancel
A38: 76227134 | B38: INFINITI OF NORTHERN KENTUCKY | C38: T-9119 | D38: 76227134 | E38: 2503481 | F38: CDK Reseller - Base Fee | G38: 300 | H38: 200 | I38: =VLOOKUP(D38,'3.10 Cancel List'!$C:$C,1,0) -> 76227134 | J38: LSS 10/01/2025 Suite Ownership Change / FOS ANS | K38: To Cancel
A39: 76227679 | B39: Express Chevrolet | C39: T-9807 | D39: 76227679 | E39: 2001988 | F39: CDK Reseller - Base Fee | G39: 300 | H39: 200 | I39: =VLOOKUP(D39,'3.10 Cancel List'!$C:$C,1,0) -> 76227679 | J39: LSS 12/25/2026 Suite CDK CONVERSION - SYS GENERATED | K39: To Retain | M39: Buy/sell new CMF | N39: 76257614
A40: 76227757 | B40: Spitzer Ford Dubois | C40: T-5725 | D40: 76227757 | E40: 2502508 | F40: CDK Reseller - Base Fee | G40: 400 | H40: 200 | I40: =VLOOKUP(D40,'3.10 Cancel List'!$C:$C,1,0) -> 76227757 | J40: LSS 12/01/2024 Standalone CDK CONVERSION | K40: To Cancel | M40: No CDK client billing
...

Sheet May Monthly Invoice- BLG Sites
A1: CMF | B1: Customer | C1: Contract Number | D1: CMF Number | E1: CID Number | F1: Item | G1: Local Amount | H1: AI fee | I1: Total Amount
A2: 01012201 | B2: Lynn Layton Chevrolet | C2: T-16228 | D2: 1012201 | E2: 3001502 | F2: CDK Reseller - Base Fee | G2: 300 | H2: 200 | I2: =G2+H2 -> 500
A3: 01012202 | B3: LYNN LAYTON CADILLAC NISSAN | C3: T-16227 | D3: 1012202 | E3: 3001510 | F3: CDK Reseller - Base Fee | G3: 300 | H3: 200 | I3: =G3+H3 -> 500
A4: 01013501 | B4: AL PACKER FORD INC | C4: T-15480 | D4: 1013501 | E4: 10027 | F4: CDK Reseller - Base Fee | G4: 300 | H4: 200 | I4: =G4+H4 -> 500
A5: 01013502 | B5: AL PACKER FORD ROYAL PALM BEACH | C5: T-15479 | D5: 1013502 | E5: 10028 | F5: CDK Reseller - Base Fee | G5: 300 | H5: 200 | I5: =G5+H5 -> 500
A6: 01029501 | B6: HAMPTON CHEVROLET - VA | C6: T-15096 | D6: 1029501 | E6: 2001100 | F6: CDK Reseller - Base Fee | G6: 300 | H6: 200 | I6: =G6+H6 -> 500
A7: 01325739 | B7: SOUTHTOWNE MOTORS OF NEWNAN | C7: T-13815 | D7: 1325739 | E7: 2000912 | F7: CDK Reseller - Base Fee | G7: 300 | H7: 200 | I7: =G7+H7 -> 500
A8: 01326145 | B8: Honda de San Juan | C8: T-16178 | D8: 1326145 | E8: 2500576 | F8: CDK Reseller - Base Fee | G8: 300 | H8: 200 | I8: =G8+H8 -> 500
A9: 08320081 | B9: BAHAMAS BUS & TRUCK CO | C9: T-10870 | D9: 8320081 | E9: 2002071 | F9: CDK Reseller - Base Fee | G9: 300 | H9: 200 | I9: =G9+H9 -> 500
A10: 09025902 | B10: BRANTFORD NISSAN | C10: T-16213 | D10: 9025902 | E10: 2002697 | F10: CDK Reseller - Base Fee | G10: 300 | H10: 200 | I10: =G10+H10 -> 500
A11: 13498058 | B11: PAT MILLIKEN FORD | C11: T-16176 | D11: 13498058 | E11: 3365 | F11: CDK Reseller - Base Fee | G11: 300 | H11: 200 | I11: =G11+H11 -> 500
A12: 17237901 | B12: WESTSIDE CHEVROLET INC. | C12: T-4374 | D12: 17237901 | E12: 2501985 | F12: CDK Reseller - Base Fee | G12: 300 | H12: 200 | I12: =G12+H12 -> 500
A13: 25111201 | B13: RYE SUBARU | C13: T-15509 | D13: 25111201 | E13: 2502986 | F13: CDK Reseller - Base Fee | G13: 300 | H13: 200 | I13: =G13+H13 -> 500
... A20: 71034933 | B20: AL PACKER FORD WHITE MARSH | C20: T-15475 | D20: 71034933 | E20: 10038 | F20: CDK Reseller - Base Fee | G20: 300 | H20: 200 | I20: =G20+H20 -> 500
A21: 71046210 | B21: PETERBILT OF UTAH, INC. | C21: T-6822 | D21: 71046210 | E21: N/A | F21: CDK Reseller - Base Fee | G21: 300 | H21: 200 | I21: =G21+H21 -> 500
A22: 71047545 | B22: FIRST TEAM HONDA | C22: T-15095 | D22: 71047545 | E22: 2001103 | F22: CDK Reseller - Base Fee | G22: 300 | H22: 200 | I22: =G22+H22 -> 500
A23: 71052261 | B23: JAY WOLFE ACURA | C23: T-15484 | D23: 71052261 | E23: 3002167 | F23: CDK Reseller - Base Fee | G23: 300 | H23: 200 | I23: =G23+H23 -> 500
A24: 71059338 | B24: FIRST TEAM TOYOTA SCION | C24: T-15094 | D24: 71059338 | E24: 2001096 | F24: CDK Reseller - Base Fee | G24: 300 | H24: 200 | I24: =G24+H24 -> 500
A25: 71061453 | B25: BURLINGTON KIA | C25: T-16233 | D25: 71061453 | E25: 3002947 | F25: CDK Reseller - Base Fee | G25: 300 | H25: 200 | I25: =G25+H25 -> 500
A26: 71064116 | B26: MERCEDES BENZ OF SOUTH ORLANDO | C26: T-14827 | D26: 71064116 | E26: 8076 | F26: CDK Reseller - Base Fee | G26: 300 | H26: 200 | I26: =G26+H26 -> 500
A27: 71064158 | B27: CASTLE CHEVROLET NORTH | C27: T-13597 | D27: 71064158 | E27: 2501853 | F27: CDK Reseller - Base Fee | G27: 300 | H27: 200 | I27: =G27+H27 -> 500
A28: 76003334 | B28: FRIENDLY FORD | C28: T-14786 | D28: 76003334 | E28: 8061 | F28: CDK Reseller - Base Fee | G28: 300 | H28: 200 | I28: =G28+H28 -> 500
A29: 76031206 | B29: MARSHALL FORD - TX | C29: T-15478 | D29: 76031206 | E29: 903072 | F29: CDK Reseller - Base Fee | G29: 300 | H29: 200 | I29: =G29+H29 -> 500
A30: 76032748 | B30: KERRY MAZDA | C30: T-16222 | D30: 76032748 | E30: 3002949 | F30: CDK Reseller - Base Fee | G30: 300 | H30: 200 | I30: =G30+H30 -> 500
A31: 76036137 | B31: SHAW GMC CHEVROLET BUICK | C31: T-16221 | D31: 76036137 | E31: 2501825 | F31: CDK Reseller - Base Fee | G31: 300 | H31: 200 | I31: =G31+H31 -> 500
A32: 76036160 | B32: GREENWOOD CHEVY OF AUSTINTOWN | C32: T-16169 | D32: 76036160 | E32: 9014 | F32: CDK Reseller - Base Fee | G32: 300 | H32: 200 | I32: =G32+H32 -> 500
A33: 76037591 | B33: LB SMITH FORD LINCOLN | C33: T-16203 | D33: 76037591 | E33: 6091 | F33: CDK Reseller - Base Fee | G33: 300 | H33: 200 | I33: =G33+H33 -> 500
A34: 76038422 | B34: ROUTE 60 HYUNDAI | C34: T-16167 | D34: 76038422 | E34: 2500295 | F34: CDK Reseller - Base Fee | G34: 300 | H34: 200 | I34: =G34+H34 -> 500
A35: 76041535 | B35: JEROME PETERBILT, INC. | C35: T-5708 | D35: 76041535 | E35: N/A | F35: CDK Reseller - Base Fee | G35: 300 | H35: 200 | I35: =G35+H35 -> 500
A36: 76043449 | B36: FELDMAN CHEVROLET OF NEW HUDSON | C36: T-15506 | D36: 76043449 | E36: 123018 | F36: CDK Reseller - Base Fee | G36: 300 | H36: 200 | I36: =G36+H36 -> 500
A37: 76043451 | B37: FELDMAN CHEVROLET OF HIGHLAND | C37: T-15505 | D37: 76043451 | E37: 123019 | F37: CDK Reseller - Base Fee | G37: 300 | H37: 200 | I37: =G37+H37 -> 500
A38: 76043453 | B38: FELDMAN HYUNDAI OF NEW HUDSON | C38: T-15085 | D38: 76043453 | E38: 0 | F38: CDK Reseller - Base Fee | G38: 300 | H38: 200 | I38: =G38+H38 -> 500
A39: 76043455 | B39: FELDMAN CHEVROLET OF NOVI | C39: T-15504 | D39: 76043455 | E39: 123021 | F39: CDK Reseller - Base Fee | G39: 300 | H39: 200 | I39: =G39+H39 -> 500
A40: 76043468 | B40: MIKE TOLER CHRYSLER DODGE JEEP | C40: T-16172 | D40: 76043468 | E40: 2001550 | F40: CDK Reseller - Base Fee | G40: 300 | H40: 200 | I40: =G40+H40 -> 500
A41: 76044062 | B41: TOYOTA SCION OF WEST COUNTY | C41: T-15483 | D41: 76044062 | E41: 2503554 | F41: CDK Reseller - Base Fee | G41: 300 | H41: 200 | I41: =G41+H41 -> 500
A42: 76072064 | B42: BMW OF SOUTHAMPTON | C42: T-16199 | D42: 76072064 | E42: 2503103 | F42: CDK Reseller - Base Fee | G42: 300 | H42: 200 | I42: =G42+H42 -> 500
A43: 76073131 | B43: SIMMONS ROCKWELL FORD - NY | C43: T-16214 | D43: 76073131 | E43: 143062 | F43: CDK Reseller - Base Fee | G43: 300 | H43: 200 | I43: =G43+H43 -> 500
A44: 76074237 | B44: FELDMAN 1800 PRE-OWNED SUPERCENTER | C44: T-15084 | D44: 76074237 | E44: 2503477 | F44: CDK Reseller - Base Fee | G44: 300 | H44: 200 | I44: =G44+H44 -> 500
A45: 76074791 | B45: ACADEMY FORD SALES | C45: T-16219 | D45: 76074791 | E45: 3002489 | F45: CDK Reseller - Base Fee | G45: 300 | H45: 200 | I45: =G45+H45 -> 500
A46: 76124458 | B46: Pepe Cadillac | C46: T-13331 | D46: 76124458 | E46: 3000121 | F46: CDK Reseller - Base Fee | G46: 300 | H46: 200 | I46: =G46+H46 -> 500
...

Sheet April Prorated Invoice-BLG Site
A1: CMF | B1: Customer | C1: CMF Number | D1: CID Number | E1: Item | F1: Local Amount | G1: CDK asked to retain
A2: =TRIM("0"&C2) -> 01012201 | B2: Lynn Layton Chevrolet | C2: 1012201 | D2: 3001502 | E2: CDK Reseller - Base Fee | F2: 40
A3: =TRIM("0"&C3) -> 01012202 | B3: LYNN LAYTON CADILLAC NISSAN | C3: 1012202 | D3: 3001510 | E3: CDK Reseller - Base Fee | F3: 100
A4: =TRIM("0"&C4) -> 01326145 | B4: Honda de San Juan | C4: 1326145 | D4: 2500576 | E4: CDK Reseller - Base Fee | F4: 290
A5: =TRIM("0"&C5) -> 09025902 | B5: BRANTFORD NISSAN | C5: 9025902 | D5: 2002697 | E5: CDK Reseller - Base Fee | F5: 160
A6: =TRIM(C6) -> 13498058 | B6: PAT MILLIKEN FORD | C6: 13498058 | D6: 3365 | E6: CDK Reseller - Base Fee | F6: 210
A7: =TRIM(C7) -> 25212501 | B7: WAYNE FORD | C7: 25212501 | D7: 6024 | E7: CDK Reseller - Base Fee | F7: 170
A8: =TRIM(C8) -> 25300610 | B8: SIMMONS ROCKWELL CHEVROLET GMC | C8: 25300610 | D8: 3002945 | E8: CDK Reseller - Base Fee | F8: 40
A9: =TRIM(C9) -> 44780001 | B9: BEECHMONT FORD | C9: 44780001 | D9: 2502046 | E9: CDK Reseller - Base Fee | F9: 90
A10: =TRIM(C10) -> 45602701 | B10: CMP CHEVY CADILLAC BUICK GMC | C10: 45602701 | D10: 2501852 | E10: CDK Reseller - Base Fee | F10: 30
A11: =TRIM(C11) -> 71061453 | B11: BURLINGTON KIA | C11: 71061453 | D11: 3002947 | E11: CDK Reseller - Base Fee | F11: 110
A12: =TRIM(C12) -> 76032748 | B12: KERRY MAZDA | C12: 76032748 | D12: 3002949 | E12: CDK Reseller - Base Fee | F12: 30
A13: =TRIM(C13) -> 76036137 | B13: SHAW GMC CHEVROLET BUICK | C13: 76036137 | D13: 2501825 | E13: CDK Reseller - Base Fee | F13: 90
A14: =TRIM(C14) -> 76036160 | B14: GREENWOOD CHEVY OF AUSTINTOWN | C14: 76036160 | D14: 9014 | E14: CDK Reseller - Base Fee | F14: 170
A15: =TRIM(C15) -> 76037591 | B15: LB SMITH FORD LINCOLN | C15: 76037591 | D15: 6091 | E15: CDK Reseller - Base Fee | F15: 160
A16: =TRIM(C16) -> 76038422 | B16: ROUTE 60 HYUNDAI | C16: 76038422 | D16: 2500295 | E16: CDK Reseller - Base Fee | F16: 300
A17: =TRIM(C17) -> 76043468 | B17: MIKE TOLER CHRYSLER DODGE JEEP | C17: 76043468 | D17: 2001550 | E17: CDK Reseller - Base Fee | F17: 280
... A88: =TRIM(C88) -> 76236503 | B88: WINSLOW FORD | C88: 76236503 | D88: 3002961 | E88: TruVideo AI Suite | F88: 20
E89: total amount | F89: =SUM(F2:F88) -> 9100.03

Sheet CDK INS not Billed by TV
A1: CMF | B1: CMF Number | C1: CDF ID | D1: Ship-To Name | E1: Catalog Number | F1: CDF Status (w/ATN) | G1: Catalog Description | H1: Consolidation Name | I1: Roll Call Date | J1: Total
A2: 05400042 | B2: 05400042 | C2: 62188525SW04 | D2: BEAVERTON KIA | E2: 4508714 | F2: INS | G2: CDK SERVICEVIEW (IN FIXED OPS PKG) | H2: LANPHERE | I2: 45638 | J2: 1
A3: 05400043 | B3: 05400043 | C3: 62188525SW11 | D3: BEAVERTON INFINITI 1 | E3: 4508714 | F3: INS | G3: CDK SERVICEVIEW (IN FIXED OPS PKG) | H3: LANPHERE | I3: 45638 | J3: 1
A4: 13115402 | B4: 13115402 | C4: 64238276SW87 | D4: BILLION HYUNDAI | E4: 4508714 | F4: INS | G4: CDK SERVICEVIEW (IN FIXED OPS PKG) | H4: BILLION | I4: 45747 | J4: 1
A5: 13115403 | B5: 13115403 | C5: 64238279SW74 | D5: BILLION DODGE CHRYSLER JEEP | E5: 4508714 | F5: INS | G5: CDK SERVICEVIEW (IN FIXED OPS PKG) | H5: BILLION | I5: 45747 | J5: 1
A6: 13497880 | B6: 13497880 | C6: 64238409SW64 | D6: WARD CHRYSLER CENTER | E6: 4508714 | F6: INS | G6: CDK SERVICEVIEW (IN FIXED OPS PKG) | H6: WARD | I6: 45748 | J6: 1
A7: 14600646 | B7: 14600646 | C7: 68233042SW04 | D7: FLOW MOTORS OF WINSTON-SALEM, LLC | E7: 4508714 | F7: INS | G7: CDK SERVICEVIEW (IN FIXED OPS PKG) | H7: FLOW COMPANIES - GROUP | I7: 45622 | J7: 1
A8: 17042101 | B8: 17042101 | C8: 64234862SW04 | D8: KNIPPELMIER CHEV INC | E8: 4508714 | F8: INS | G8: CDK SERVICEVIEW (IN FIXED OPS PKG) | H8: KNIPPELMIER CHEVROLET INC. | I8: 45639 | J8: 1
A9: 17150701 | B9: 17150701 | C9: 62188549SW04 | D9: MAC HAIK CHEV | E9: 4508714 | F9: INS | G9: CDK SERVICEVIEW (IN FIXED OPS PKG) | H9: MAC HAIK AUTO GROUP | I9: 45638 | J9: 1
A10: 25298834 | B10: 25298834 | C10: 68243943SW69 | D10: RUGE'S CHRYSLER DODGE JEEP RAM | E10: 4508714 | F10: INS | G10: CDK SERVICEVIEW (IN FIXED OPS PKG) | H10: RUGE | I10: 45930 | J10: 1
A11: 25300234 | B11: 25300234 | C11: 68245295SW83 | D11: SIMMONS ROCKWELL BUICK GMC OF ELMIRA | E11: 4508714 | F11: INS | G11: CDK SERVICEVIEW (IN FIXED OPS PKG) | H11: SIMMONS ROCKWELL | I11: 45967 | J11: 1
A12: 29012602 | B12: 29012602 | C12: 01354704SW50 | D12: MORREY NISSAN | E12: 4408593 | F12: INS | G12: CDK SERVICEVIEW IN PKG (CHILD CATALOG NUMBER FOR CDK SERVICE BUNDLE) | H12: MORREY | I12: 45721 | J12: 1
A13: 33118201 | B13: 33118201 | C13: 68233615SW08 | D13: LINDSAY HONDA | E13: 4408593 | F13: INS | G13: CDK SERVICEVIEW IN PKG (CHILD CATALOG NUMBER FOR CDK SERVICE BUNDLE) | H13: LINDSAY AUTOMOTIVE | I13: 45636 | J13: 1
A14: 33118203 | B14: 33118203 | C14: 68233615SW13 | D14: LINDSAY ACURA | E14: 4408593 | F14: INS | G14: CDK SERVICEVIEW IN PKG (CHILD CATALOG NUMBER FOR CDK SERVICE BUNDLE) | H14: LINDSAY AUTOMOTIVE | I14: 45636 | J14: 1
A15: 37119401 | B15: 37119401 | C15: 62188525SW18 | D15: BEAVERTON HONDA | E15: 4508714 | F15: INS | G15: CDK SERVICEVIEW (IN FIXED OPS PKG) | H15: LANPHERE | I15: 45638 | J15: 1
... A49: 76127638 | B49: 76127638 | C49: 68233042SW75 | D49: FLOW AUTOBAHN, LLC | E49: 4508714 | F49: INS | G49: CDK SERVICEVIEW (IN FIXED OPS PKG) | H49: FLOW COMPANIES - GROUP | I49: 45622 | J49: 1
A50: 76127639 | B50: 76127639 | C50: 68233047SW04 | D50: FLOW AUTOMOTIVE CENTER OF WINSTON-SALEM, LLC | E50: 4508714 | F50: INS | G50: CDK SERVICEVIEW (IN FIXED OPS PKG) | H50: FLOW COMPANIES - GROUP | I50: 45622 | J50: Saskatoon North Hyundai Genesis
A51: 76127658 | B51: 76127658 | C51: 68233047SW11 | D51: FLOW AUDI VOLKSWAGEN OF GREENSBORO | E51: 4508714 | F51: INS | G51: CDK SERVICEVIEW (IN FIXED OPS PKG) | H51: FLOW COMPANIES - GROUP | I51: 45622 | J51: 1
A52: 76127658 | B52: 76127658 | C52: 68233047SW18 | D52: FLOW AUDI VOLKSWAGEN OF GREENSBORO | E52: 4508714 | F52: INS | G52: CDK SERVICEVIEW (IN FIXED OPS PKG) | H52: FLOW COMPANIES - GROUP | I52: 45622 | J52: 1
A53: 76127659 | B53: 76127659 | C53: 68233047SW67 | D53: FLOW AUTO OF FAYETTEVILLE | E53: 4508714 | F53: INS | G53: CDK SERVICEVIEW (IN FIXED OPS PKG) | H53: FLOW COMPANIES - GROUP | I53: 45622 | J53: 1
A54: 76127679 | B54: 76127679 | C54: 68233047SW74 | D54: FLOW BUICK GMC LAND ROVER MAZDA OF GREENSBORO | E54: 4508714 | F54: INS | G54: CDK SERVICEVIEW (IN FIXED OPS PKG) | H54: FLOW COMPANIES - GROUP | I54: 45622 | J54: 1
A55: 76127679 | B55: 76127679 | C55: 68233047SW81 | D55: FLOW BUICK GMC LAND ROVER MAZDA OF GREENSBORO | E55: 4508714 | F55: INS | G55: CDK SERVICEVIEW (IN FIXED OPS PKG) | H55: FLOW COMPANIES - GROUP | I55: 45622 | J55: 1
A56: 76139117 | B56: 76139117 | C56: 68233048SW04 | D56: FLOW LEAN SERVICE, LLC | E56: 4508714 | F56: INS | G56: CDK SERVICEVIEW (IN FIXED OPS PKG) | H56: FLOW COMPANIES - GROUP | I56: 45622 | J56: 1
A57: 76150784 | B57: 76150784 | C57: 62198326SW58 | D57: JAGUAR LAND ROVER SAN JUAN | E57: 4508714 | F57: INS | G57: CDK SERVICEVIEW (IN FIXED OPS PKG) | H57: HELLER-BIRD AUTO GROUP | I57: 46085 | J57: 1
A58: 76155716 | B58: 76155716 | C58: 68233047SW25 | D58: FLOW HONDA OF STATESVILLE | E58: 4508714 | F58: INS | G58: CDK SERVICEVIEW (IN FIXED OPS PKG) | H58: FLOW COMPANIES - GROUP | I58: 45622 | J58: 1
A59: 76159995 | B59: 76159995 | C59: 68233047SW32 | D59: FLOW VOLKSWAGEN OF BURLINGTON | E59: 4508714 | F59: INS | G59: CDK SERVICEVIEW (IN FIXED OPS PKG) | H59: FLOW COMPANIES - GROUP | I59: 45622 | J59: 1
A60: 76160175 | B60: 76160175 | C60: 62190591SW87 | D60: ACURA OF PORTLAND | E60: 4508714 | F60: INS | G60: CDK SERVICEVIEW (IN FIXED OPS PKG) | H60: DICK HANNAH | I60: 45726 | J60: 1
A61: 76160177 | B61: 76160177 | C61: 62190592SW43 | D61: DICK HANNAH TOYOTA | E61: 4508714 | F61: INS | G61: CDK SERVICEVIEW (IN FIXED OPS PKG) | H61: DICK HANNAH | I61: 45726 | J61: 1
A62: 76160178 | B62: 76160178 | C62: 62190593SW04 | D62: DICK HANNAH VOLKSWAGEN | E62: 4508714 | F62: INS | G62: CDK SERVICEVIEW (IN FIXED OPS PKG) | H62: DICK HANNAH | I62: 45726 | J62: 1
... A149: 76259847 | B149: 76259847 | C149: 68250022SW85 | D149: VANN YORK KIA | E149: 4508714 | F149: INS | G149: CDK SERVICEVIEW (IN FIXED OPS PKG) | H149: VANN YORK | I149: 46101 | J149: 1
J150: =SUM(J2:J149) -> 148

Sheet CDK asked to retain list
A1: Store Name | B1: Comments | C1: CMF | D1: Exclude for May non INS gap list | E1: Exclude from May BLG gap list | H1: CMF # | I1: CMF | J1: Store Name
A2: Ken Ganley Toyota | B2: not installed on TV invoice | C2: 76202516 | D2: yes | H2: =TRIM(I2) -> 25149301 | I2: 25149301 | J2: WESTBROOK HONDA
A3: MODERN INFINITI OF GREENSBORO | B3: moved to Installed, and matched | C3: 71043922 | H3: =TRIM(I3) -> 25149306 | I3: 25149306 | J3: TOYOTA OF WESTBROOK
A4: HONDA OF WATERTOWN | B4: moved to Installed, and matched | C4: 71042332 | H4: =TRIM(I4) -> 71042332 | I4: 71042332 | J4: HONDA OF WATERTOWN
A5: Saskatoon North Hyundai Genesis | B5: moved to Installed, and matched | C5: 76204181 | H5: =TRIM(I5) -> 71043922 | I5: 71043922 | J5: MODERN INFINITI OF GREENSBORO
A6: Saskatoon South Hyundai | B6: not installed on TV invoice | C6: 76204182 | D6: yes | H6: =TRIM(I6) -> 76001666 | I6: 76001666 | J6: KOEPPEL NISSAN
A7: TOYOTA OF WESTBROOK | B7: moved to BLG in CDK | C7: 25149306 | E7: yes | H7: =TRIM(I7) -> 76028715 | I7: 76028715 | J7: JOHNSON HYUNDAI OF CARY
A8: WESTBROOK HONDA | B8: moved to BLG in CDK | C8: 25149301 | E8: yes | H8: =TRIM(I8) -> 76051500 | I8: 76051500 | J8: RED BANK VOLVO
A9: HGREG NISSAN BUENA PARK | B9: not installed on TV invoice | C9: 76225712 | D9: Yes | H9: =TRIM(I9) -> 76074807 | I9: 76074807 | J9: SUPERIOR CHEVROLET
A10: JOHNSON HYUNDAI OF CARY | B10: not installed on TV invoice | C10: 76028715 | D10: Yes | H10: =TRIM(I10) -> 76097658 | I10: 76097658 | J10: STATELINE MASERATI ALFA ROMEO
A11: KOEPPEL NISSAN | B11: not installed on TV invoice | C11: 76001666 | D11: Yes | H11: =TRIM(I11) -> 76202516 | I11: 76202516 | J11: Ken Ganley Toyota
A12: ROCKY MOUNT TOYOTA | B12: not installed on TV invoice | C12: 76217358 | D12: Yes | H12: =TRIM(I12) -> 76204181 | I12: 76204181 | J12: Saskatoon North Hyundai Genesis
A13: STATELINE MASERATI ALFA ROMEO | B13: not installed on TV invoice | C13: 76097658 | D13: Yes | H13: =TRIM(I13) -> 76204182 | I13: 76204182 | J13: Saskatoon South Hyundai
A14: SUPERIOR CHEVROLET | B14: not on TV invoice, CDK shows LSS | C14: 76074807 | H14: =TRIM(I14) -> 76209246 | I14: 76209246 | J14: Scenic Chevrolet GMC Subaru
A15: RED BANK VOLVO | B15: not installed on TV invoice | C15: 76051500 | D15: Yes | H15: =TRIM(I15) -> 76217358 | I15: 76217358 | J15: ROCKY MOUNT TOYOTA
A16: Scenic Chevrolet GMC Subaru | B16: moved to BLG in CDK | C16: 76209246 | E16: Yes | H16: =TRIM(I16) -> 76225712 | I16: 76225712 | J16: HGREG NISSAN BUENA PARK
H17: =TRIM(I17) -> 76227679 | I17: 76227679 | J17: Express Chevrolet
H18: =TRIM(I18) -> 76228316 | I18: 76228316 | J18: Genesis West Houston
H19: =TRIM(I19) -> 76229253 | I19: 76229253 | J19: BRAVO NISSAN OF VICTORIA
A20: additional to ratain sites found on May 19 | H20: =TRIM(I20) -> 76238760 | I20: 76238760 | J20: FRED ANDERSON NISSAN OF GREER
A21: 76227679 | B21: Express Chevrolet | H21: =TRIM(I21) -> 76241447 | I21: 76241447 | J21: LAND ROVER SHREVEPORT.1
A22: 76228316 | B22: Genesis West Houston | H22: =TRIM(I22) -> 76241522 | I22: 76241522 | J22: SMAIL FORD
A23: 76229253 | B23: BRAVO NISSAN OF VICTORIA | H23: =TRIM(I23) -> 76245003 | I23: 76245003 | J23: GRUBBS NISSAN
A24: 76238760 | B24: FRED ANDERSON NISSAN OF GREER | H24: =TRIM(I24) -> 76250378 | I24: 76250378 | J24: GALEANA CDJR MT. PLEASANT
A25: 76241447 | B25: LAND ROVER SHREVEPORT.1
A26: 76241522 | B26: SMAIL FORD
A27: 76245003 | B27: GRUBBS NISSAN
A28: 76250378 | B28: GALEANA CDJR MT. PLEASANT

Sheet TV active sites in March Cancel
A1: CMF | B1: Customer | C1: Partner ID# | D1: Contract Number | E1: Customer Number | F1: TV ID | G1: MOST_RECENT_VIDEO | H1: Asked by CDK to retain | I1: BuySell New CMF | J1: Billed in May? | K1: Comments
A2: =TRIM(C2) -> 08310080 | B2: C. Harper Ford KIA | C2: 08310080 | D2: T-8969 | E2: T-8209 | F2: 6240 | G2: 46121.657 | H2: =VLOOKUP(C2,'CDK asked to retain list'!$C$2:$C$16,1,0) -> #N/A | J2: No
A3: =TRIM(C3) -> 13345702 | B3: RUSS DARROW CHRYSLER DODGE JEEP WEST BEND | C3: 13345702 | D3: T-4258 | E3: T-3236 | F3: 3102 | G3: 46121.664 | H3: =VLOOKUP(C3,'CDK asked to retain list'!$C$2:$C$16,1,0) -> #N/A | J3: No
A4: =TRIM(C4) -> 25149301 | B4: WESTBROOK HONDA | C4: 25149301 | D4: T-14524 | E4: T-12723 | F4: 6567 | G4: 46121.664 | H4: Yes | J4: =VLOOKUP(C4,'TV May Monthly Billing Sites'!$D:$F,1,0) -> 25149301
A5: =TRIM(C5) -> 25149302 | B5: HONDA OF WATERTOWN | C5: 25149302 | D5: T-9440 | E5: T-8576 | F5: 6623 | G5: 46121.653 | H5: =VLOOKUP(C5,'CDK asked to retain list'!$C$2:$C$16,1,0) -> #N/A | J5: =VLOOKUP(C5,'TV May Monthly Billing Sites'!$D:$F,1,0) -> 25149302 | K5: CDK in BLG
A6: =TRIM(C6) -> 25149303 | B6: ACURA OF AVON | C6: 25149303 | D6: T-9439 | E6: T-8575 | F6: 6565 | G6: 46121.624 | H6: =VLOOKUP(C6,'CDK asked to retain list'!$C$2:$C$16,1,0) -> #N/A | J6: No
A7: =TRIM(C7) -> 25149306 | B7: TOYOTA OF WESTBROOK | C7: 25149306 | D7: T-9607 | E7: T-8705 | F7: 6712 | G7: 46113.746 | H7: Yes | J7: =VLOOKUP(C7,'TV May Monthly Billing Sites'!$D:$F,1,0) -> 25149306
A8: =TRIM(C8) -> 71043922 | B8: MODERN INFINITI OF GREENSBORO | C8: 71043922 | D8: T-7482 | E8: T-6426 | F8: 5152 | G8: 46121.662 | H8: Yes | J8: =VLOOKUP(C8,'TV May Monthly Billing Sites'!$D:$F,1,0) -> 71043922
A9: =TRIM(C9) -> 71046175 | B9: Myers Auto Group | C9: 71046175 | D9: T-8089 | E9: T-6921 | F9: 5679 | G9: 46121.551 | H9: =VLOOKUP(C9,'CDK asked to retain list'!$C$2:$C$16,1,0) -> #N/A | J9: No
A10: =TRIM(C10) -> 71048561 | B10: CAR PROS KIA | C10: 71048561 | D10: T-8975 | E10: T-8215 | F10: 6258 | G10: 46121.654 | H10: =VLOOKUP(C10,'CDK asked to retain list'!$C$2:$C$16,1,0) -> #N/A | J10: No
A11: =TRIM(C11) -> 76001666 | B11: KOEPPEL NISSAN | C11: 76001666 | D11: T-4093 | E11: T-7811 | F11: 2297 | G11: 46120.754 | H11: Yes | I11: 76254215 | J11: =VLOOKUP(C11,'TV May Monthly Billing Sites'!$D:$F,1,0) -> 76001666
A12: =TRIM(C12) -> 76028715 | B12: JOHNSON HYUNDAI OF CARY | C12: 76028715 | D12: T-4067 | E12: T-2669 | F12: 2728 | G12: 46121.652 | H12: Yes | I12: 76244599 | J12: =VLOOKUP(C12,'TV May Monthly Billing Sites'!$D:$F,1,0) -> 76028715
A13: =TRIM(C13) -> 76051500 | B13: RED BANK VOLVO | C13: 76051500 | D13: T-8026 | E13: T-6865 | F13: 5632 | G13: 46121.656 | H13: Yes | I13: 76258384 | J13: =VLOOKUP(C13,'TV May Monthly Billing Sites'!$D:$F,1,0) -> 76051500
A14: =TRIM(C14) -> 76064391 | B14: FINDLAY VOLKSWAGEN OF ST GEORGE | C14: 76064391 | D14: T-4460 | E14: T-4087 | F14: 3380 | G14: 46121.634 | H14: =VLOOKUP(C14,'CDK asked to retain list'!$C$2:$C$16,1,0) -> #N/A | J14: No
A15: =TRIM(C15) -> 76074807 | B15: SUPERIOR CHEVROLET | C15: 76074807 | D15: T-9144 | E15: T-2227 | F15: 2155 | G15: 46121.591 | H15: Yes | I15: 76252069 | J15: No
A16: =TRIM(C16) -> 76074807 | B16: SUPERIOR CHEVROLET | C16: 76074807 | D16: T-4308 | E16: T-2227 | F16: 2155 | G16: 46121.591 | H16: Yes | J16: No
A17: =TRIM(C17) -> 76082339 | B17: Ford Lincoln Fairfield | C17: 76082339 | D17: T-3941 | E17: T-3219 | F17: 3096 | G17: 46121.639 | H17: =VLOOKUP(C17,'CDK asked to retain list'!$C$2:$C$16,1,0) -> #N/A | J17: No
A18: =TRIM(C18) -> 76097658 | B18: STATELINE MASERATI ALFA ROMEO | C18: 76097658 | D18: T-14496 | E18: T-12699 | F18: 7901 | G18: 46120.765 | H18: Yes | I18: 76257430 | J18: =VLOOKUP(C18,'TV May Monthly Billing Sites'!$D:$F,1,0) -> 76097658
A19: =TRIM(C19) -> 76141529 | B19: Al Spitzer Ford Cuyahoga Falls | C19: 76141529 | D19: T-5724 | E19: T-4774 | F19: 3779 | G19: 46121.662 | H19: =VLOOKUP(C19,'CDK asked to retain list'!$C$2:$C$16,1,0) -> #N/A | J19: No
A20: =TRIM(C20) -> 76141532 | B20: Spitzer Ford Hartville | C20: 76141532 | D20: T-5733 | E20: T-4783 | F20: 3655 | G20: 46121.619 | H20: =VLOOKUP(C20,'CDK asked to retain list'!$C$2:$C$16,1,0) -> #N/A | J20: No
A21: =TRIM(C21) -> 76153399 | B21: CAR PROS RENTON HYUNDAI | C21: 76153399 | D21: T-8976 | E21: T-8216 | F21: 6259 | G21: 46121.644 | H21: =VLOOKUP(C21,'CDK asked to retain list'!$C$2:$C$16,1,0) -> #N/A | J21: No
A22: =TRIM(C22) -> 76157327 | B22: MARINA DEL REY TOYOTA SCION | C22: 76157327 | D22: T-4118 | E22: T-2728 | F22: 2804 | G22: 46120.804 | H22: =VLOOKUP(C22,'CDK asked to retain list'!$C$2:$C$16,1,0) -> #N/A | J22: =VLOOKUP(C22,'TV May Monthly Billing Sites'!$D:$F,1,0) -> 76157327 | K22: ANS toyota inspect package, INS non SV inspect bundle. Inactive customer for SV
A23: =TRIM(C23) -> 76166159 | B23: ELYRIA HYUNDAI | C23: 76166159 | D23: T-8302 | E23: T-7618 | F23: 5917 | G23: 46115.706 | H23: =VLOOKUP(C23,'CDK asked to retain list'!$C$2:$C$16,1,0) -> #N/A | J23: No | K23: will be rekeyed to have SV.
A24: =TRIM(C24) -> 76174859 | B24: SIMMONS-ROCKWELL SUBARU MITSUBISHI | C24: 76174859 | D24: T-8790 | E24: T-8068 | F24: 6100 | G24: 46121.648 | H24: =VLOOKUP(C24,'CDK asked to retain list'!$C$2:$C$16,1,0) -> #N/A | J24: No
A25: =TRIM(C25) -> 76180664 | B25: CAR PROS KIA RENTON | C25: 76180664 | D25: T-8977 | E25: T-8217 | F25: 6257 | G25: 46121.603 | H25: =VLOOKUP(C25,'CDK asked to retain list'!$C$2:$C$16,1,0) -> #N/A | I25: 76256639 | J25: No | K25: new CMF 76256639/ Go Kai Renton
A26: =TRIM(C26) -> 76202516 | B26: KEN GANLEY TOYOTA | C26: 76202516 | D26: T-6016 | E26: T-5095 | F26: 3929 | G26: 46121.639 | H26: Yes | J26: =VLOOKUP(C26,'TV May Monthly Billing Sites'!$D:$F,1,0) -> 76202516
A27: =TRIM(C27) -> 76204181 | B27: Saskatoon North Hyundai Genesis | C27: 76204181 | D27: T-9599 | E27: T-3488 | F27: 3075 | G27: 46121.619 | H27: Yes | J27: =VLOOKUP(C27,'TV May Monthly Billing Sites'!$D:$F,1,0) -> 76204181
A28: =TRIM(C28) -> 76204182 | B28: Saskatoon South Hyundai | C28: 76204182 | D28: T-9598 | E28: T-3124 | F28: 3074 | G28: 46121.664 | H28: Yes | J28: =VLOOKUP(C28,'TV May Monthly Billing Sites'!$D:$F,1,0) -> 76204182
A29: =TRIM(C29) -> 76204947 | B29: GRIECO HYUNDAI | C29: 76204947 | D29: T-6776 | E29: T-5812 | F29: 4803 | G29: 46121.511 | H29: =VLOOKUP(C29,'CDK asked to retain list'!$C$2:$C$16,1,0) -> #N/A | J29: No
A30: =TRIM(C30) -> 76207079 | B30: Gengras Volkswagen of Plainville | C30: 76207079 | D30: T-6765 | E30: T-5801 | F30: 4544 | G30: 46121.628 | H30: =VLOOKUP(C30,'CDK asked to retain list'!$C$2:$C$16,1,0) -> #N/A | J30: No
A31: =TRIM(C31) -> 76209246 | B31: Scenic Chevrolet GMC Subaru | C31: 76209246 | D31: T-9822 | E31: T-8876 | F31: 6937 | G31: 46121.654 | H31: Yes | J31: already billed under new CMF
A32: =TRIM(C32) -> 76217358 | B32: ROCKY MOUNT TOYOTA | C32: 76217358 | D32: T-4254 | E32: T-2717 | F32: 2784 | G32: 46121.647 | H32: Yes | I32: 76244695 | J32: =VLOOKUP(C32,'TV May Monthly Billing Sites'!$D:$F,1,0) -> 76217358
A33: =TRIM(C33) -> 76219463 | B33: PREMIER CAPE COD | C33: 76219463 | D33: T-4228 | E33: T-2380 | F33: 2375 | G33: 46121.664 | H33: =VLOOKUP(C33,'CDK asked to retain list'!$C$2:$C$16,1,0) -> #N/A | J33: No
A34: =TRIM(C34) -> 76225712 | B34: HGREG NISSAN BUENA PARK | C34: 76225712 | D34: T-3995 | E34: T-2706 | F34: 2749 | G34: 46121.662 | H34: Yes | I34: 76257313 | J34: =VLOOKUP(C34,'TV May Monthly Billing Sites'!$D:$F,1,0) -> 76225712

Sheet CDK Cancel tracking 5.16.26
A1: CMF | B1: Dealer Name | C1: CMF # | D1: Service/Dealer Code | E1: Date Loss Requested | F1: Cancel Reason | G1: On Lei List | H1: Notes
A2: ="0"&TRIM(C2) -> 01196701 | B2: Coastal Hyundai | C2: 1196701 | D2: 845834 | E2: 46092 | H2: Recent
A3: ="0"&TRIM(C3) -> 01325978 | B3: Maxie Price Chevrolet | C3: 1325978 | D3: 512350 | E3: 46091 | F3: Low Utilization | H3: Recent
A4: ="0"&TRIM(C4) -> 05139104 | B4: Maita Chevrolet | C4: 5139104 | D4: 466845 | E4: 46091 | F4: DMS Provider Change | H4: Recent
A5: ="0"&TRIM(C5) -> 05236442 | B5: Smothers European | C5: 5236442 | D5: 62045 | E5: 46143 | F5: Changed DMS Provider
A6: ="0"&TRIM(C6) -> 07615206 | B6: Toyota Del Rio | C6: 7615206 | D6: 024996 | E6: 46093 | H6: Recent
A7: ="0"&TRIM(C7) -> 07621134 | B7: Anderson Ford | C7: 7621134 | D7: 544664 | E7: 46091 | F7: Low Utilization | H7: Recent
A8: ="0"&TRIM(C8) -> 07624170 | B8: Ford of Spartanburg | C8: 7624170 | D8: 768457 | E8: 46092 | H8: Recent
A9: ="0"&TRIM(C9) -> 08300018 | B9: Grainger Honda | C9: 8300018 | D9: 282414 | E9: 46146 | F9: No Comment
A10: ="0"&TRIM(C10) -> 08300127 | B10: Prestige Imports | C10: 8300127 | D10: 188030 | E10: 46059 | F10: Low Utilization | G10: No
A11: ="0"&TRIM(C11) -> 09800035 | B11: Van Buren Buick GMC - DealerID 6554 | C11: 9800035 | D11: 6554 | E11: 46027 | G11: Yes
A12: =TRIM(C12) -> 17314868 | B12: Sames Ford Laredo | C12: 17314868 | D12: 305057 | E12: 46042 | F12: DMS Provider Change | G12: Yes | H12: On Loss list from Lei SAMES MOTOR COMPANY Same CMF
A13: =TRIM(C13) -> 17315776 | B13: Sames Honda | C13: 17315776 | D13: 163617 | E13: 46093 | F13: Low Utilization | H13: Recent
A14: =TRIM(C14) -> 37002901 | B14: Len Lyall Chevrolet | C14: 37002901 | D14: 664881 | E14: 46093 | H14: Recent
A15: =TRIM(C15) -> 37011801 | B15: Jerry Seiner Chevrolet Cadillac Kia Salt Lake | C15: 37011801 | D15: 305755 | E15: 46090 | G15: Yes | H15: Recent
A16: =TRIM(C16) -> 37011804 | B16: Jerry Seiner Buick GMS North Salt Lake | C16: 37011804 | D16: 526414 | E16: 46090 | F16: Low Utilization | G16: Yes | H16: Recent
A17: =TRIM(C17) -> 43996001 | B17: Paul MIller Audi | C17: 43996001 | D17: 451374 | E17: 46146 | F17: Changed provider
A18: =TRIM(C18) -> 71038202 | B18: Aiport Chevrolet | C18: 71038202 | D18: 560288 | E18: 46141 | F18: Cancelled
A19: =TRIM(C19) -> 71046604 | B19: The Chevrolet Exchange | C19: 71046604 | D19: 526554 | E19: 46093 | H19: Recent
A20: =TRIM(C20) -> 71052821 | B20: Schicker Ford St. Louis - Dealer ID 3000872 | C20: 71052821 | D20: 513030 | E20: 46119 | F20: incompatible
A21: =TRIM(C21) -> 71052902 | B21: Caldwell Toyota | C21: 71052902 | D21: 358008 | E21: 46093 | F21: Changed Vendors | H21: Recent
A22: =TRIM(C22) -> 71065039 | B22: Toyota Tacoma | C22: 71065039 | D22: 308822 | E22: 46142 | F22: DmS Provider Change
A23: =TRIM(C23) -> 76002916 | B23: Bentley Paramus - DealerID 2139 | C23: 76002916 | D23: 2139 | E23: 46031 | G23: No
A24: =TRIM(C24) -> 76012651 | B24: Findlay Honda Henderson | C24: 76012651 | D24: 350208 | E24: 46093 | F24: Low Utilization | H24: Recent
A25: =TRIM(C25) -> 76024029 | B25: Damerow Ford | C25: 76024029 | D25: 385244 | E25: 46142
A26: =TRIM(C26) -> 76024700 | B26: Cannon Chevrolet Buick Cadillac | C26: 76024700 | D26: 506664 | E26: 46093 | F26: Low Utilization | H26: Recent
A27: =TRIM(C27) -> 76027610 | B27: Valley Hi Honda | C27: 76027610 | D27: 580262 | E27: 46142 | F27: Changed vendors
A28: =TRIM(C28) -> 76038829 | B28: Sames Bastrop Ford | C28: 76038829 | D28: 822458 | E28: 46042 | F28: DMS Provider Change | H28: On Loss list from Lei SAMES MOTOR COMPANY Different CMF
A29: =TRIM(C29) -> 76039933 | B29: Chaparral Buick GMC | C29: 76039933 | D29: 214382 | E29: 46092 | H29: Recent
A30: =TRIM(C30) -> 76042015 | B30: Mag Volvo Cars Dublin | C30: 76042015 | D30: 304806 | E30: 46093 | F30: Changed DMS Provider | H30: Recent
A31: =TRIM(C31) -> 76043277 | B31: Paul Miller Honda West Caldwell | C31: 76043277 | D31: 545776 | E31: 46146 | F31: Changed provider
A32: =TRIM(C32) -> 76043322 | B32: Rancho Grand Motors Buick GMC | C32: 76043322 | D32: 647815 | E32: 46091 | F32: Changed Vendors | H32: Recent
A33: =TRIM(C33) -> 76054901 | B33: Midwestern Auto Group | C33: 76054901 | D33: 72400 | E33: 46093 | F33: Changed DMS Provider | H33: Recent
A34: =TRIM(C34) -> 76057761 | B34: Jeff Schmitt Mazda | C34: 76057761 | D34: 803007 | E34: 46128 | F34: Changed providers
A35: =TRIM(C35) -> 76062180 | B35: Volvo Car Pioneer Valley | C35: 76062180 | D35: 31421 | E35: 46134 | F35: Dealer closed
A36: =TRIM(C36) -> 76066680 | B36: Speedway Chevrolet | C36: 76066680 | D36: 41080 | E36: 46090 | F36: Low Utilization | G36: Yes | H36: Recent- Reinstated 4/8/26 per Ryan Reed
A37: =TRIM(C37) -> 76072111 | B37: Gebhardt BMW | C37: 76072111 | D37: 865628 | E37: 46093 | H37: Recent
A38: =TRIM(C38) -> 76073768 | B38: Lexington Toyota | C38: 76073768 | D38: 418053 | E38: 46093 | F38: Low Utilization | H38: Recent
A39: =TRIM(C39) -> 76080698 | B39: Hyundai Inland Empire | C39: 76080698 | D39: 608705 | E39: 46091 | F39: Low Utilization | H39: Recent
A40: =TRIM(C40) -> 76140116 | B40: Roseburg Honda | C40: 76140116 | D40: 138421 | E40: 46092 | H40: Recent
...

Sheet TV May Monthly Billing Sites
A1: CMF | B1: Customer | C1: Contract Number | D1: CMF Number | E1: CID Number | F1: Item | G1: Local Amount | H1: Found in CDK INS by CMF | I1: Found in CDK INS by Name | J1: Found in CDK BLG by CMF | K1: Found in CDK BLG by Name | L1: New Sites in April | M1: To Retain List
A2: ="0"&TRIM(D2) -> 01012201 | B2: Lynn Layton Chevrolet | C2: T-16228 | D2: 1012201 | E2: 3001502 | F2: CDK Reseller - Base Fee | G2: 300 | H2: =VLOOKUP(A2,'SV Child INS Apr'!$A:$H,1,0) -> #N/A | I2: =VLOOKUP(B2,'SV Child INS Apr'!$D:$F,1,0) -> #N/A | J2: =VLOOKUP(A2,'SV Child BLG Apr'!$A:$J,1,0) -> 01012201 | L2: =VLOOKUP(A2,'TV Apr Prorated Billing Sites'!$A:$I,1,0) -> 01012201 | M2: =VLOOKUP(A2,'CDK asked to retain list'!$H$1:$J$24,1,0) -> #N/A
A3: ="0"&TRIM(D3) -> 01012202 | B3: LYNN LAYTON CADILLAC NISSAN | C3: T-16227 | D3: 1012202 | E3: 3001510 | F3: CDK Reseller - Base Fee | G3: 300 | H3: =VLOOKUP(A3,'SV Child INS Apr'!$A:$H,1,0) -> #N/A | I3: =VLOOKUP(B3,'SV Child INS Apr'!$D:$F,1,0) -> #N/A | J3: =VLOOKUP(A3,'SV Child BLG Apr'!$A:$J,1,0) -> 01012202 | L3: =VLOOKUP(A3,'TV Apr Prorated Billing Sites'!$A:$I,1,0) -> 01012202 | M3: =VLOOKUP(A3,'CDK asked to retain list'!$H$1:$J$24,1,0) -> #N/A
A4: ="0"&TRIM(D4) -> 01012401 | B4: Solomon Chevrolet Cadillac | C4: T-11243 | D4: 1012401 | E4: 2500033 | F4: CDK Reseller - Base Fee | G4: 300 | H4: =VLOOKUP(A4,'SV Child INS Apr'!$A:$H,1,0) -> 01012401 | L4: =VLOOKUP(A4,'TV Apr Prorated Billing Sites'!$A:$I,1,0) -> #N/A
A5: ="0"&TRIM(D5) -> 01013001 | B5: Tameron Honda | C5: T-10927 | D5: 1013001 | E5: 2503657 | F5: CDK Reseller - Base Fee | G5: 300 | H5: =VLOOKUP(A5,'SV Child INS Apr'!$A:$H,1,0) -> 01013001 | L5: =VLOOKUP(A5,'TV Apr Prorated Billing Sites'!$A:$I,1,0) -> #N/A
